Workbook

Sheet CropNitrousEstimationDefaultFac
A1: IPCC Crop types | B1: Slope (T) | C1: Intercept (T) | D1: N content of AG residues | E1: RS (T) | F1: N BG(T)
A2: Generic value | B2: 0 | C2: 0 | D2: 0.008 | E2: 0.22 | F2: 0.009
A3: Grains | B3: 1.09 | C3: 0.88 | D3: 0.006 | E3: 0.22 | F3: 0.009
A4: Beans & pulses | B4: 1.13 | C4: 0.85 | D4: 0.008 | E4: 0.19 | F4: 0.008
A5: Tubers | B5: 0.1 | C5: 1.06 | D5: 0.019 | E5: 0.2 | F5: 0.014
A6: Root crops | B6: 1.07 | C6: 1.54 | D6: 0.019 | E6: 0.2 | F6: 0.014
A7: N-fixing forages | B7: 0.3 | C7: 0 | D7: 0.027 | E7: 0.4 | F7: 0.022
A8: Non-N-fixing forages | B8: 0.3 | C8: 0 | D8: 0.015 | E8: 0.54 | F8: 0.012
A9: Maize | B9: 1.03 | C9: 0.61 | D9: 0.006 | E9: 0.22 | F9: 0.007
A10: Wheat | B10: 1.51 | C10: 0.52 | D10: 0.006 | E10: 0.24 | F10: 0.009
A11: Winter wheat | B11: 1.61 | C11: 0.4 | D11: 0.006 | E11: 0.23 | F11: 0.009
A12: Spring wheat | B12: 1.29 | C12: 0.75 | D12: 0.006 | E12: 0.28 | F12: 0.009
A13: Rice | B13: 0.95 | C13: 2.46 | D13: 0.007 | E13: 0.16 | F13: 0.009
... A26: Grass-clover mixtures | B26: 0.3 | C26: 0 | D26: 0.025 | E26: 0.8 | F26: 0.016

Sheet FAO crop mapping
A1: Default factors for estimating N from crop residues and forage/pasture renewal
A2: Table 11.2
A3: IPCC Crop types | B3: Dry matter fraction harvested product | C3: Slope | D3: Intercept | E3: N content of AG residues | F3: Rag | G3: Rs | H3: N content of BG residues
A4: Generic grains | B4: 0.88 | C4: 1.09 | D4: 0.88 | E4: 0.006 | F4: 1.3 | G4: 0.22 | H4: 0.009
A5: Wheat | B5: 0.89 | C5: 1.51 | D5: 0.52 | E5: =AVERAGE(0.006,0.006) -> 0.006 | F5: =AVERAGE(1.3,1.3) -> 1.3 | G5: =AVERAGE(0.23,0.28) -> 0.255 | H5: =AVERAGE(0.009,0.009) -> 0.009
A6: Barley | B6: 0.89 | C6: 0.98 | D6: 0.59 | E6: 0.007 | F6: 1.2 | G6: 0.22 | H6: 0.014
A7: Oats | B7: 0.89 | C7: 0.91 | D7: 0.89 | E7: 0.007 | F7: 1.3 | G7: 0.25 | H7: 0.008
A8: Maize | B8: 0.87 | C8: 1.03 | D8: 0.61 | E8: 0.006 | F8: 1 | G8: 0.22 | H8: 0.007
A9: Rye | B9: 0.88 | C9: 1.09 | D9: 0.88 | E9: 0.005 | F9: 1.6 | H9: 0.011
A10: Rice | B10: 0.89 | C10: 0.95 | D10: 2.46 | E10: 0.007 | F10: 1.4 | G10: 0.16
A11: Millet | B11: 0.9 | C11: 1.43 | D11: 0.14 | E11: 0.007 | F11: 1.4
A12: Sorghum | B12: 0.89 | C12: 0.88 | D12: 1.33 | E12: 0.007 | F12: 1.4 | H12: 0.006
A13: Beans and pulses | B13: 0.91 | C13: 1.13 | D13: 0.85 | E13: 0.008 | F13: 2.1 | G13: 0.19 | H13: 0.008
A14: Soybeans | B14: 0.91 | C14: 0.93 | D14: 1.35 | E14: 0.008 | F14: 2.1 | G14: 0.19 | H14: 0.008
A15: Potatoes & tubers | B15: 0.22 | C15: 0.1 | D15: 1.06 | E15: 0.019 | F15: 0.4 | G15: 0.2 | H15: 0.014
A16: Peanuts | B16: 0.94 | C16: 1.07 | D16: 1.54 | E16: 0.016 | F16: 1 | G16: 0.1
A17: Notes:
A20: Default factors for estimating N from crop residues and forage/pasture renewal
A21: Adapted from Table 11.2
A22: FAO crops | B22: Dry matter fraction harvested product | C22: Slope | D22: Intercept | E22: N content of AG residues | F22: Rag | G22: Rs | H22: N content of BG residues
A23: Bambara beans | B23: =B41 -> 0.94 | C23: =C41 -> 1.07 | D23: =D41 -> 1.54 | E23: =E41 -> 0.016 | F23: =F41 -> 1 | G23: =G41 -> 0.1 | H23: =H41 -> 0
A24: Barley | B24: 1 | C24: =C6 -> 0.98 | D24: =D6 -> 0.59 | E24: =E6 -> 0.007 | F24: =F6 -> 1.2 | G24: =G6 -> 0.22 | H24: =H6 -> 0.014
A25: Beans, dry | B25: 1 | C25: =C13 -> 1.13 | D25: =D13 -> 0.85 | E25: =E13 -> 0.008 | F25: =F13 -> 2.1 | G25: =G13 -> 0.19 | H25: =H13 -> 0.008
A26: Broad beans, horse beans, dry | B26: 1 | C26: =C25 -> 1.13 | D26: =D25 -> 0.85 | E26: =E25 -> 0.008 | F26: =F25 -> 2.1 | G26: =G25 -> 0.19 | H26: =H25 -> 0.008
A27: Buckwheat | B27: =B36 -> 0.88 | C27: =C36 -> 1.09 | D27: =D36 -> 0.88 | E27: =E36 -> 0.006 | F27: =F36 -> 1.3 | G27: =G36 -> 0.22 | H27: =H36 -> 0.009
A28: Carrots and turnips | B28: 0.22 | C28: =C45 -> 0.1 | D28: =D45 -> 1.06 | E28: =E45 -> 0.019 | F28: =F45 -> 0.4 | G28: =G45 -> 0.2 | H28: =H45 -> 0.014
A29: Cassava | B29: 0.22 | C29: =C45 -> 0.1 | D29: =D45 -> 1.06 | E29: =E45 -> 0.019 | F29: =F45 -> 0.4 | G29: =G45 -> 0.2 | H29: =H45 -> 0.014
A30: Cereals | B30: =B36 -> 0.88 | C30: =C36 -> 1.09 | D30: =D36 -> 0.88 | E30: =E36 -> 0.006 | F30: =F36 -> 1.3 | G30: =G36 -> 0.22 | H30: =H36 -> 0.009
A31: Chick peas | B31: =B26 -> 1 | C31: =C26 -> 1.13 | D31: =D26 -> 0.85 | E31: =E26 -> 0.008 | F31: =F26 -> 2.1 | G31: =G26 -> 0.19 | H31: =H26 -> 0.008
A32: Chicory roots | B32: 0.22 | C32: =C45 -> 0.1 | D32: =D45 -> 1.06 | E32: =E45 -> 0.019 | F32: =F45 -> 0.4 | G32: =G45 -> 0.2 | H32: =H45 -> 0.014
A33: Cow peas, dry | B33: =B26 -> 1 | C33: =C26 -> 1.13 | D33: =D26 -> 0.85 | E33: =E26 -> 0.008 | F33: =F26 -> 2.1 | G33: =G26 -> 0.19 | H33: =H26 -> 0.008
A34: Flooded rice | B34: =B10 -> 0.89 | C34: =C10 -> 0.95 | D34: =D10 -> 2.46 | E34: =E10 -> 0.007 | F34: =F10 -> 1.4 | G34: =G10 -> 0.16 | H34: =H10 -> 0
A35: Fonio | B35: =B36 -> 0.88 | C35: =C36 -> 1.09 | D35: =D36 -> 0.88 | E35: =E36 -> 0.006 | F35: =F36 -> 1.3 | G35: =G36 -> 0.22 | H35: =H36 -> 0.009
A36: Grain, mixed | B36: =B4 -> 0.88 | C36: =C4 -> 1.09 | D36: =D4 -> 0.88 | E36: =E4 -> 0.006 | F36: =F4 -> 1.3 | G36: =G4 -> 0.22 | H36: =H4 -> 0.009
A37: Lentils | B37: =B26 -> 1 | C37: =C26 -> 1.13 | D37: =D26 -> 0.85 | E37: =E26 -> 0.008 | F37: =F26 -> 2.1 | G37: =G26 -> 0.19 | H37: =H26 -> 0.008
A38: Maize | B38: 1 | C38: =C8 -> 1.03 | D38: =D8 -> 0.61 | E38: =E8 -> 0.006 | F38: =F8 -> 1 | G38: =G8 -> 0.22 | H38: =H8 -> 0.007
A39: Millet | B39: 1 | C39: =C11 -> 1.43 | D39: =D11 -> 0.14 | E39: =E11 -> 0.007 | F39: =F11 -> 1.4 | G39: =G11 -> 0 | H39: =H11 -> 0
A40: Oats | B40: 1 | C40: =C7 -> 0.91 | D40: =D7 -> 0.89 | E40: =E7 -> 0.007 | F40: =F7 -> 1.3 | G40: =G7 -> 0.25 | H40: =H7 -> 0.008
A41: Peanuts | B41: =B16 -> 0.94 | C41: =C16 -> 1.07 | D41: =D16 -> 1.54 | E41: =E16 -> 0.016 | F41: =F16 -> 1 | G41: =G16 -> 0.1 | H41: =H16 -> 0
A42: Peas, dry | B42: =B26 -> 1 | C42: =C26 -> 1.13 | D42: =D26 -> 0.85 | E42: =E26 -> 0.008 | F42: =F26 -> 2.1 | G42: =G26 -> 0.19 | H42: =H26 -> 0.008
...

Sheet Final_list
A1: item | B1: ONLINE | C1: CROPYIELDSTATS | D1: Dry matter fraction harvested product | E1: Slope | F1: Intercept | G1: N content of AG residues | H1: Rag | I1: Rs | J1: N content of BG residues
A2: Generic value | B2: YES | C2: YES | D2: 0.88 | E2: 1.09 | F2: 0.88 | G2: 0.006 | H2: 1.3 | I2: 0.22 | J2: 0.009
A3: Abaca, manila hemp, raw | B3: YES | C3: NO | D3: =IF(B3="yes",VLOOKUP(A3,'FAO crop mapping'!$A$22:$H$60,2,FALSE), "") -> #N/A | E3: =IF(B3="yes",VLOOKUP(A3,'FAO crop mapping'!$A$22:$H$60,3,FALSE), "") -> #N/A | F3: =IF(B3="yes",VLOOKUP(A3,'FAO crop mapping'!$A$22:$H$60,4,FALSE), "") -> #N/A | G3: =IF(B3="yes",VLOOKUP(A3,'FAO crop mapping'!$A$22:$H$60,5,FALSE), "") -> #N/A | H3: =IF(B4="yes",VLOOKUP(A4,'FAO crop mapping'!$A$22:$H$60,6,FALSE), "") | I3: =IF(B4="yes",VLOOKUP(A4,'FAO crop mapping'!$A$22:$H$60,7,FALSE), "") | J3: =IF(B4="yes",VLOOKUP(A4,'FAO crop mapping'!$A$22:$H$60,8,FALSE), "")
A4: Agave fibres, raw, n.e.c. | B4: NO | C4: NO | D4: =IF(B4="yes",VLOOKUP(A4,'FAO crop mapping'!$A$22:$H$60,2,FALSE), "") | E4: =IF(B4="yes",VLOOKUP(A4,'FAO crop mapping'!$A$22:$H$60,3,FALSE), "") | F4: =IF(B4="yes",VLOOKUP(A4,'FAO crop mapping'!$A$22:$H$60,4,FALSE), "") | G4: =IF(B4="yes",VLOOKUP(A4,'FAO crop mapping'!$A$22:$H$60,5,FALSE), "") | H4: =IF(B5="yes",VLOOKUP(A5,'FAO crop mapping'!$A$22:$H$60,6,FALSE), "") -> #N/A | I4: =IF(B5="yes",VLOOKUP(A5,'FAO crop mapping'!$A$22:$H$60,7,FALSE), "") -> #N/A | J4: =IF(B5="yes",VLOOKUP(A5,'FAO crop mapping'!$A$22:$H$60,8,FALSE), "") -> #N/A
A5: Almonds, in shell | B5: YES | C5: YES | D5: =IF(B5="yes",VLOOKUP(A5,'FAO crop mapping'!$A$22:$H$60,2,FALSE), "") -> #N/A | E5: =IF(B5="yes",VLOOKUP(A5,'FAO crop mapping'!$A$22:$H$60,3,FALSE), "") -> #N/A | F5: =IF(B5="yes",VLOOKUP(A5,'FAO crop mapping'!$A$22:$H$60,4,FALSE), "") -> #N/A | G5: =IF(B5="yes",VLOOKUP(A5,'FAO crop mapping'!$A$22:$H$60,5,FALSE), "") -> #N/A | H5: =IF(B6="yes",VLOOKUP(A6,'FAO crop mapping'!$A$22:$H$60,6,FALSE), "") -> #N/A | I5: =IF(B6="yes",VLOOKUP(A6,'FAO crop mapping'!$A$22:$H$60,7,FALSE), "") -> #N/A | J5: =IF(B6="yes",VLOOKUP(A6,'FAO crop mapping'!$A$22:$H$60,8,FALSE), "") -> #N/A
A6: Anise, badian, coriander, cumin, caraway, fennel and juniper berries, raw | B6: YES | C6: NO | D6: =IF(B6="yes",VLOOKUP(A6,'FAO crop mapping'!$A$22:$H$60,2,FALSE), "") -> #N/A | E6: =IF(B6="yes",VLOOKUP(A6,'FAO crop mapping'!$A$22:$H$60,3,FALSE), "") -> #N/A | F6: =IF(B6="yes",VLOOKUP(A6,'FAO crop mapping'!$A$22:$H$60,4,FALSE), "") -> #N/A | G6: =IF(B6="yes",VLOOKUP(A6,'FAO crop mapping'!$A$22:$H$60,5,FALSE), "") -> #N/A | H6: =IF(B7="yes",VLOOKUP(A7,'FAO crop mapping'!$A$22:$H$60,6,FALSE), "") -> #N/A | I6: =IF(B7="yes",VLOOKUP(A7,'FAO crop mapping'!$A$22:$H$60,7,FALSE), "") -> #N/A | J6: =IF(B7="yes",VLOOKUP(A7,'FAO crop mapping'!$A$22:$H$60,8,FALSE), "") -> #N/A
A7: Apples | B7: YES | C7: NO | D7: =IF(B7="yes",VLOOKUP(A7,'FAO crop mapping'!$A$22:$H$60,2,FALSE), "") -> #N/A | E7: =IF(B7="yes",VLOOKUP(A7,'FAO crop mapping'!$A$22:$H$60,3,FALSE), "") -> #N/A | F7: =IF(B7="yes",VLOOKUP(A7,'FAO crop mapping'!$A$22:$H$60,4,FALSE), "") -> #N/A | G7: =IF(B7="yes",VLOOKUP(A7,'FAO crop mapping'!$A$22:$H$60,5,FALSE), "") -> #N/A | H7: =IF(B8="yes",VLOOKUP(A8,'FAO crop mapping'!$A$22:$H$60,6,FALSE), "") -> #N/A | I7: =IF(B8="yes",VLOOKUP(A8,'FAO crop mapping'!$A$22:$H$60,7,FALSE), "") -> #N/A | J7: =IF(B8="yes",VLOOKUP(A8,'FAO crop mapping'!$A$22:$H$60,8,FALSE), "") -> #N/A
A8: Apricots | B8: YES | C8: NO | D8: =IF(B8="yes",VLOOKUP(A8,'FAO crop mapping'!$A$22:$H$60,2,FALSE), "") -> #N/A | E8: =IF(B8="yes",VLOOKUP(A8,'FAO crop mapping'!$A$22:$H$60,3,FALSE), "") -> #N/A | F8: =IF(B8="yes",VLOOKUP(A8,'FAO crop mapping'!$A$22:$H$60,4,FALSE), "") -> #N/A | G8: =IF(B8="yes",VLOOKUP(A8,'FAO crop mapping'!$A$22:$H$60,5,FALSE), "") -> #N/A | H8: =IF(B9="yes",VLOOKUP(A9,'FAO crop mapping'!$A$22:$H$60,6,FALSE), "") -> #N/A | I8: =IF(B9="yes",VLOOKUP(A9,'FAO crop mapping'!$A$22:$H$60,7,FALSE), "") -> #N/A | J8: =IF(B9="yes",VLOOKUP(A9,'FAO crop mapping'!$A$22:$H$60,8,FALSE), "") -> #N/A
A9: Areca nuts | B9: YES | C9: NO | D9: =IF(B9="yes",VLOOKUP(A9,'FAO crop mapping'!$A$22:$H$60,2,FALSE), "") -> #N/A | E9: =IF(B9="yes",VLOOKUP(A9,'FAO crop mapping'!$A$22:$H$60,3,FALSE), "") -> #N/A | F9: =IF(B9="yes",VLOOKUP(A9,'FAO crop mapping'!$A$22:$H$60,4,FALSE), "") -> #N/A | G9: =IF(B9="yes",VLOOKUP(A9,'FAO crop mapping'!$A$22:$H$60,5,FALSE), "") -> #N/A | H9: =IF(B10="yes",VLOOKUP(A10,'FAO crop mapping'!$A$22:$H$60,6,FALSE), "") -> #N/A | I9: =IF(B10="yes",VLOOKUP(A10,'FAO crop mapping'!$A$22:$H$60,7,FALSE), "") -> #N/A | J9: =IF(B10="yes",VLOOKUP(A10,'FAO crop mapping'!$A$22:$H$60,8,FALSE), "") -> #N/A
A10: Artichokes | B10: YES | C10: NO | D10: =IF(B10="yes",VLOOKUP(A10,'FAO crop mapping'!$A$22:$H$60,2,FALSE), "") -> #N/A | E10: =IF(B10="yes",VLOOKUP(A10,'FAO crop mapping'!$A$22:$H$60,3,FALSE), "") -> #N/A | F10: =IF(B10="yes",VLOOKUP(A10,'FAO crop mapping'!$A$22:$H$60,4,FALSE), "") -> #N/A | G10: =IF(B10="yes",VLOOKUP(A10,'FAO crop mapping'!$A$22:$H$60,5,FALSE), "") -> #N/A | H10: =IF(B11="yes",VLOOKUP(A11,'FAO crop mapping'!$A$22:$H$60,6,FALSE), "") -> #N/A | I10: =IF(B11="yes",VLOOKUP(A11,'FAO crop mapping'!$A$22:$H$60,7,FALSE), "") -> #N/A | J10: =IF(B11="yes",VLOOKUP(A11,'FAO crop mapping'!$A$22:$H$60,8,FALSE), "") -> #N/A
A11: Asparagus | B11: YES | C11: NO | D11: =IF(B11="yes",VLOOKUP(A11,'FAO crop mapping'!$A$22:$H$60,2,FALSE), "") -> #N/A | E11: =IF(B11="yes",VLOOKUP(A11,'FAO crop mapping'!$A$22:$H$60,3,FALSE), "") -> #N/A | F11: =IF(B11="yes",VLOOKUP(A11,'FAO crop mapping'!$A$22:$H$60,4,FALSE), "") -> #N/A | G11: =IF(B11="yes",VLOOKUP(A11,'FAO crop mapping'!$A$22:$H$60,5,FALSE), "") -> #N/A | H11: =IF(B12="yes",VLOOKUP(A12,'FAO crop mapping'!$A$22:$H$60,6,FALSE), "") | I11: =IF(B12="yes",VLOOKUP(A12,'FAO crop mapping'!$A$22:$H$60,7,FALSE), "") | J11: =IF(B12="yes",VLOOKUP(A12,'FAO crop mapping'!$A$22:$H$60,8,FALSE), "")
A12: Asses | B12: NO | C12: NO | D12: =IF(B12="yes",VLOOKUP(A12,'FAO crop mapping'!$A$22:$H$60,2,FALSE), "") | E12: =IF(B12="yes",VLOOKUP(A12,'FAO crop mapping'!$A$22:$H$60,3,FALSE), "") | F12: =IF(B12="yes",VLOOKUP(A12,'FAO crop mapping'!$A$22:$H$60,4,FALSE), "") | G12: =IF(B12="yes",VLOOKUP(A12,'FAO crop mapping'!$A$22:$H$60,5,FALSE), "") | H12: =IF(B13="yes",VLOOKUP(A13,'FAO crop mapping'!$A$22:$H$60,6,FALSE), "") -> #N/A | I12: =IF(B13="yes",VLOOKUP(A13,'FAO crop mapping'!$A$22:$H$60,7,FALSE), "") -> #N/A | J12: =IF(B13="yes",VLOOKUP(A13,'FAO crop mapping'!$A$22:$H$60,8,FALSE), "") -> #N/A
A13: Avocados | B13: YES | C13: YES | D13: =IF(B13="yes",VLOOKUP(A13,'FAO crop mapping'!$A$22:$H$60,2,FALSE), "") -> #N/A | E13: =IF(B13="yes",VLOOKUP(A13,'FAO crop mapping'!$A$22:$H$60,3,FALSE), "") -> #N/A | F13: =IF(B13="yes",VLOOKUP(A13,'FAO crop mapping'!$A$22:$H$60,4,FALSE), "") -> #N/A | G13: =IF(B13="yes",VLOOKUP(A13,'FAO crop mapping'!$A$22:$H$60,5,FALSE), "") -> #N/A | H13: =IF(B14="yes",VLOOKUP(A14,'FAO crop mapping'!$A$22:$H$60,6,FALSE), "") | I13: =IF(B14="yes",VLOOKUP(A14,'FAO crop mapping'!$A$22:$H$60,7,FALSE), "") | J13: =IF(B14="yes",VLOOKUP(A14,'FAO crop mapping'!$A$22:$H$60,8,FALSE), "")
A14: Balata, gutta-percha, guayule, chicle and similar natural gums in primary forms or in plates, sheets or strip | B14: NO | C14: NO | D14: =IF(B14="yes",VLOOKUP(A14,'FAO crop mapping'!$A$22:$H$60,2,FALSE), "") | E14: =IF(B14="yes",VLOOKUP(A14,'FAO crop mapping'!$A$22:$H$60,3,FALSE), "") | F14: =IF(B14="yes",VLOOKUP(A14,'FAO crop mapping'!$A$22:$H$60,4,FALSE), "") | G14: =IF(B14="yes",VLOOKUP(A14,'FAO crop mapping'!$A$22:$H$60,5,FALSE), "") | H14: =IF(B15="yes",VLOOKUP(A15,'FAO crop mapping'!$A$22:$H$60,6,FALSE), "") -> #N/A | I14: =IF(B15="yes",VLOOKUP(A15,'FAO crop mapping'!$A$22:$H$60,7,FALSE), "") -> #N/A | J14: =IF(B15="yes",VLOOKUP(A15,'FAO crop mapping'!$A$22:$H$60,8,FALSE), "") -> #N/A
... A333: Sheep and Goats > (List) | B333: NO | C333: NO | D333: =IF(B333="yes",VLOOKUP(A333,'FAO crop mapping'!$A$22:$H$60,2,FALSE), "") | E333: =IF(B333="yes",VLOOKUP(A333,'FAO crop mapping'!$A$22:$H$60,3,FALSE), "") | F333: =IF(B333="yes",VLOOKUP(A333,'FAO crop mapping'!$A$22:$H$60,4,FALSE), "") | G333: =IF(B333="yes",VLOOKUP(A333,'FAO crop mapping'!$A$22:$H$60,5,FALSE), "") | H333: =IF(B334="yes",VLOOKUP(A334,'FAO crop mapping'!$A$22:$H$60,6,FALSE), "") | I333: =IF(B334="yes",VLOOKUP(A334,'FAO crop mapping'!$A$22:$H$60,7,FALSE), "") | J333: =IF(B334="yes",VLOOKUP(A334,'FAO crop mapping'!$A$22:$H$60,8,FALSE), "")
B334: NO | C334: NO | D334: =IF(B334="yes",VLOOKUP(A334,'FAO crop mapping'!$A$22:$H$60,2,FALSE), "") | E334: =IF(B334="yes",VLOOKUP(A334,'FAO crop mapping'!$A$22:$H$60,3,FALSE), "") | F334: =IF(B334="yes",VLOOKUP(A334,'FAO crop mapping'!$A$22:$H$60,4,FALSE), "") | G334: =IF(B334="yes",VLOOKUP(A334,'FAO crop mapping'!$A$22:$H$60,5,FALSE), "")

Sheet Final_values
A1: ITEM | B1: ONLINE | C1: CROPYIELDSTATS | D1: DRY MATTER FRACTION HARVESTED | E1: SLOPE | F1: INTERCEPT | G1: N CONTENT OF AG RESIDUES | H1: RAG | I1: RS | J1: N CONTENT OF BG RESIDUES | K1: COMMENTS
A2: Generic value | B2: YES | C2: YES | D2: 0.88 | E2: 1.09 | F2: 0.88 | G2: 0.006 | H2: 1.3 | I2: 0.22 | J2: 0.009 | K2: Values already provided in Final_list.
A3: Abaca, manila hemp, raw | B3: YES | C3: NO | D3: 0.88 | E3: 1.09 | F3: 0.88 | G3: 0.006 | H3: 1.3 | I3: 0.22 | J3: 0.009 | K3: Remaining missing values filled with Generic value defaults
A4: Agave fibres, raw, n.e.c. | B4: NO | C4: NO | K4: Non-crop/processed/aggregate item (ONLINE and CROPYIELDSTATS are not YES); residue factors not populated.
A5: Almonds, in shell | B5: YES | C5: YES | D5: 0.88 | E5: 1.09 | F5: 0.88 | G5: 0.006 | H5: 1.3 | I5: 0.22 | J5: 0.009 | K5: Approximated using mapping for 'Cereals' based on name/commodity match. Tree nuts harvested as dry seeds: proxied to Cereals as conservative seed-crop approximation.
A6: Anise, badian, coriander, cumin, caraway, fennel and juniper berries, raw | B6: YES | C6: NO | D6: 0.88 | E6: 1.09 | F6: 0.88 | G6: 0.006 | H6: 1.3 | I6: 0.22 | J6: 0.009 | K6: Remaining missing values filled with Generic value defaults
A7: Apples | B7: YES | C7: NO | D7: 0.22 | E7: 0.1 | F7: 1.06 | G7: 0.019 | H7: 0.4 | I7: 0.2 | J7: 0.014 | K7: Approximated using mapping for 'Potatoes' based on name/commodity match. Fruit crop: used Potatoes proxy as conservative fresh-produce approximation (high moisture).
A8: Apricots | B8: YES | C8: NO | D8: 0.22 | E8: 0.1 | F8: 1.06 | G8: 0.019 | H8: 0.4 | I8: 0.2 | J8: 0.014 | K8: Approximated using mapping for 'Potatoes' based on name/commodity match. Fruit crop: used Potatoes proxy as conservative fresh-produce approximation (high moisture).
A9: Areca nuts | B9: YES | C9: NO | D9: 0.88 | E9: 1.09 | F9: 0.88 | G9: 0.006 | H9: 1.3 | I9: 0.22 | J9: 0.009 | K9: Approximated using mapping for 'Cereals' based on name/commodity match. Tree nuts harvested as dry seeds: proxied to Cereals as conservative seed-crop approximation.
A10: Artichokes | B10: YES | C10: NO | D10: 0.22 | E10: 0.1 | F10: 1.06 | G10: 0.019 | H10: 0.4 | I10: 0.2 | J10: 0.014 | K10: Approximated using mapping for 'Potatoes' based on name/commodity match. Vegetable crop: used Potatoes proxy as conservative fresh-produce approximation (high moisture).
A11: Asparagus | B11: YES | C11: NO | D11: 0.22 | E11: 0.1 | F11: 1.06 | G11: 0.019 | H11: 0.4 | I11: 0.2 | J11: 0.014 | K11: Approximated using mapping for 'Potatoes' based on name/commodity match. Vegetable crop: used Potatoes proxy as conservative fresh-produce approximation (high moisture).
A12: Asses | B12: NO | C12: NO | K12: Non-crop/processed/aggregate item (ONLINE and CROPYIELDSTATS are not YES); residue factors not populated.
A13: Avocados | B13: YES | C13: YES | D13: 0.22 | E13: 0.1 | F13: 1.06 | G13: 0.019 | H13: 0.4 | I13: 0.2 | J13: 0.014 | K13: Approximated using mapping for 'Potatoes' based on name/commodity match. Fruit crop: used Potatoes proxy as conservative fresh-produce approximation (high moisture).
A14: Balata, gutta-percha, guayule, chicle and similar natural gums in primary forms or in plates, sheets or strip | B14: NO | C14: NO | K14: Non-crop/processed/aggregate item (ONLINE and CROPYIELDSTATS are not YES); residue factors not populated.
A15: Bambara beans, dry | B15: YES | C15: NO | D15: 0.94 | E15: 1.07 | F15: 1.54 | G15: 0.016 | H15: 1 | I15: 0.1 | J15: 0 | K15: Approximated using mapping for 'Peanuts'
A16: Bananas | B16: YES | C16: NO | D16: 0.22 | E16: 0.1 | F16: 1.06 | G16: 0.019 | H16: 1.2 | I16: 0.22 | J16: 0.014 | K16: Approximated using mapping for 'Potatoes' based on name/commodity match. Fruit crop: used Potatoes proxy as conservative fresh-produce approximation (high moisture).
A17: Barley | B17: YES | C17: NO | D17: 1 | E17: 0.98 | F17: 0.59 | G17: 0.007 | H17: 2.1 | I17: 0.19 | J17: 0.008 | K17: Values already provided in Final_list.
A18: Beans, dry | B18: YES | C18: YES | D18: 1 | E18: 1.13 | F18: 0.85 | G18: 0.008 | H18: 2.1 | I18: 0.19 | J18: 0.008 | K18: Filled missing values from IPCC and FAO crops mapping). Exact match to FAO crop 'Beans, dry'.
A19: Beer of barley, malted | B19: NO | C19: NO | K19: Non-crop/processed/aggregate item (ONLINE and CROPYIELDSTATS are not YES); residue factors not populated.
A20: Bees | B20: NO | C20: NO | K20: Non-crop/processed/aggregate item (ONLINE and CROPYIELDSTATS are not YES); residue factors not populated.
A21: Beeswax | B21: NO | C21: NO | K21: Non-crop/processed/aggregate item (ONLINE and CROPYIELDSTATS are not YES); residue factors not populated.
A22: Blueberries | B22: YES | C22: NO | D22: 0.22 | E22: 0.1 | F22: 1.06 | G22: 0.019 | H22: 0.4 | I22: 0.2 | J22: 0.014 | K22: Approximated using mapping for 'Potatoes' based on name/commodity match. Fruit crop: used Potatoes proxy as conservative fresh-produce approximation (high moisture).
A23: Brazil nuts, in shell | B23: YES | C23: NO | D23: 0.88 | E23: 1.09 | F23: 0.88 | G23: 0.006 | H23: 1.3 | I23: 0.22 | J23: 0.009 | K23: Approximated using mapping for 'Cereals' based on name/commodity match. Tree nuts harvested as dry seeds: proxied to Cereals as conservative seed-crop approximation.
A24: Broad beans and horse beans, dry | B24: NO | C24: NO | K24: Non-crop/processed/aggregate item (ONLINE and CROPYIELDSTATS are not YES); residue factors not populated.
A25: Broad beans and horse beans, green | B25: NO | C25: NO | H25: 1.3 | I25: 0.22 | J25: 0.009 | K25: Non-crop/processed/aggregate item (ONLINE and CROPYIELDSTATS are not YES); residue factors not populated.
A26: Buckwheat | B26: YES | C26: YES | D26: 0.88 | E26: 1.09 | F26: 0.88 | G26: 0.006 | H26: 1.3 | I26: 0.22 | J26: 0.009 | K26: Filled missing values from IPCC and FAO crops mapping). Exact match to FAO crop 'Buckwheat'.
A27: Buffalo | B27: NO | C27: NO | K27: Non-crop/processed/aggregate item (ONLINE and CROPYIELDSTATS are not YES); residue factors not populated.
A28: Buffalo fat, unrendered | B28: NO | C28: NO | K28: Non-crop/processed/aggregate item (ONLINE and CROPYIELDSTATS are not YES); residue factors not populated.
A29: Butter and ghee of sheep milk | B29: NO | C29: NO | K29: Non-crop/processed/aggregate item (ONLINE and CROPYIELDSTATS are not YES); residue factors not populated.
A30: Butter of buffalo milk | B30: NO | C30: NO | K30: Non-crop/processed/aggregate item (ONLINE and CROPYIELDSTATS are not YES); residue factors not populated.
A31: Butter of cow milk | B31: NO | C31: NO | K31: Non-crop/processed/aggregate item (ONLINE and CROPYIELDSTATS are not YES); residue factors not populated.
A32: Butter of goat milk | B32: NO | C32: NO | K32: Non-crop/processed/aggregate item (ONLINE and CROPYIELDSTATS are not YES); residue factors not populated.
A33: Buttermilk, dry | B33: NO | C33: NO | K33: Non-crop/processed/aggregate item (ONLINE and CROPYIELDSTATS are not YES); residue factors not populated.
A34: Cabbages | B34: YES | C34: NO | D34: 0.22 | E34: 0.1 | F34: 1.06 | G34: 0.019 | H34: 0.4 | I34: 0.2 | J34: 0.014 | K34: Approximated using mapping for 'Potatoes' based on name/commodity match. Vegetable crop: used Potatoes proxy as conservative fresh-produce approximation (high moisture).
A35: Camels | B35: NO | C35: NO | K35: Non-crop/processed/aggregate item (ONLINE and CROPYIELDSTATS are not YES); residue factors not populated.
A36: Canary seed | B36: YES | C36: NO | D36: 0.88 | E36: 1.09 | F36: 0.88 | G36: 0.006 | H36: 1.3 | I36: 0.22 | J36: 0.009 | K36: Remaining missing values filled with Generic value defaults
A37: Cantaloupes and other melons | B37: YES | C37: NO | D37: 0.22 | E37: 0.1 | F37: 1.06 | G37: 0.019 | H37: 0.4 | I37: 0.2 | J37: 0.014 | K37: Approximated using mapping for 'Potatoes' based on name/commodity match. Fruit crop: used Potatoes proxy as conservative fresh-produce approximation (high moisture).
A38: Carrots and turnips | B38: YES | C38: NO | D38: 0.22 | E38: 0.1 | F38: 1.06 | G38: 0.019 | H38: 0.4 | I38: 0.2 | J38: 0.014 | K38: Filled missing values from IPCC and FAO crops mapping). Exact match to FAO crop 'Carrots and turnips'.
A39: Cashew nuts, in shell | B39: YES | C39: YES | D39: 0.88 | E39: 1.09 | F39: 0.88 | G39: 0.006 | H39: 1.3 | I39: 0.22 | J39: 0.009 | K39: Approximated using mapping for 'Cereals' based on name/commodity match. Tree nuts harvested as dry seeds: proxied to Cereals as conservative seed-crop approximation.
A40: Cashewapple | B40: NO | C40: NO | K40: Non-crop/processed/aggregate item (ONLINE and CROPYIELDSTATS are not YES); residue factors not populated.
...

Sheet Annualsperennials
A1: ITEM | B1: ONLINE | C1: CROPYIELDSTATS | D1: ANNUALS | E1: PERENNIALS
A2: Generic value | B2: YES | C2: YES | D2: YES | E2: YES
A3: Abaca, manila hemp, raw | B3: YES | C3: NO | D3: NO | E3: YES
A4: Almonds, in shell | B4: YES | C4: YES | D4: NO | E4: YES
A5: Anise, badian, coriander, cumin, caraway, fennel and juniper berries, raw | B5: YES | C5: NO | D5: YES | E5: NO
A6: Apples | B6: YES | C6: NO | D6: NO | E6: YES
A7: Apricots | B7: YES | C7: NO | D7: NO | E7: YES
A8: Areca nuts | B8: YES | C8: NO | D8: NO | E8: YES
A9: Artichokes | B9: YES | C9: NO | D9: YES | E9: NO
A10: Asparagus | B10: YES | C10: NO | D10: YES | E10: NO
A11: Avocados | B11: YES | C11: YES | D11: NO | E11: YES
A12: Bambara beans, dry | B12: YES | C12: NO | D12: YES | E12: NO
... A145: Vegetables Primary + (Total) | B145: YES | C145: YES | D145: YES | E145: NO
