Workbook
Name Activitiesbalance: Graph!$G$29:INDEX(Graph!$G$29:$G$40,COUNT(Graph!$G$29:$G$40))
Name ActivitiesWith: Graph!$G$59:INDEX(Graph!$G$59:$G$70,COUNT(Graph!$G$59:$G$70))
Name ActivitiesWithout: Graph!$G$44:INDEX(Graph!$G$44:$G$55,COUNT(Graph!$G$44:$G$55))
Name AMWS_Breeding_Swine_HP_titles: IPCC!$A$2487:$P$2487
Name AMWS_Chicken_broiler_LP_titles: IPCC!$A$2640:$P$2640
Name AMWS_Growing_Swine_HP_titles: IPCC!$A$2521:$P$2521
Name AWMS_Breeding_Swine_LP_titles: IPCC!$A$2504:$P$2504
Name AWMS_Chicken_broiler_HP_titles: IPCC!$A$2623:$P$2623
Name AWMS_Chicken_Layer_Default_titles: IPCC!$A$2606:$P$2606
Name AWMS_Dairy_Buffalo_titles: IPCC!$A$2453:$P$2453
Name AWMS_Dairy_Cattle_titles: IPCC!$A$2419:$P$2419
Name AWMS_Deer_titles: IPCC!$A$2691:$P$2691
Name AWMS_Goat_titles: IPCC!$A$2589:$P$2589
Name AWMS_Growing_Swine_LP_titles: IPCC!$A$2538:$P$2538
Name AWMS_Ostrich_titles: IPCC!$A$2674:$P$2674
Name AWMS_Other_Buffalo_titles: IPCC!$A$2470:$P$2470
Name AWMS_Other_Cattle_titles: IPCC!$A$2436:$P$2436
Name AWMS_Other_Grazing_titles: IPCC!$A$2657:$P$2657
Name AWMS_Other_Sheep_titles: IPCC!$A$2555:$P$2555
Name AWMS_Sheep_dairy_titles: IPCC!$A$2572:$P$2572
Name Boreal: defo!$D$9:$D$14
Name Boreal2: affo!$D$8:$D$13
Name CH4_man_Camel_HP_titles: IPCC!$A$2912:$P$2912
Name CH4_man_Camel_LP_titles: IPCC!$A$2929:$P$2929
Name CH4_man_Dairy_Cattle_HP_titles: IPCC!$A$2708:$P$2708
Name CH4_man_Dairy_Cattle_LP_titles: IPCC!$A$2725:$P$2725
Name CH4_man_Goat_HP_titles: IPCC!$A$2878:$P$2878
Name CH4_man_Goat_LP_titles: IPCC!$A$2895:$P$2895
Name CH4_man_Horse_HP_titles: IPCC!$A$2946:$P$2946
Name CH4_man_Horse_LP_titles: IPCC!$A$2963:$P$2963
Name CH4_man_Mule_HP_titles: IPCC!$A$2980:$P$2980
Name CH4_man_Mule_LP_titles: IPCC!$A$2997:$P$2997
Name CH4_man_Other_Cattle_HP_titles: IPCC!$A$2742:$P$2742
Name CH4_man_Other_Cattle_LP_titles: IPCC!$A$2759:$P$2759
Name CH4_man_Poultry_HP_titles: IPCC!$A$2810:$P$2810
Name CH4_man_Poultry_LP_titles: IPCC!$A$2827:$P$2827
Name CH4_man_Sheep_HP_titles: IPCC!$A$2844:$P$2844
Name CH4_man_Sheep_LP_titles: IPCC!$A$2861:$P$2861
Name CH4_man_Swine_HP_titles: IPCC!$A$2776:$P$2776
Name CH4_man_Swine_LP_titles: IPCC!$A$2793:$P$2793
Name clim_moist: list!$I$8
Name clim_moist_cont: list!$I$9
Name clim3: list!$I$12
Name climate: '1.Description'!$Q$10
Name climate2: list!$I$11
Name continent: '1.Description'!$Q$8
Name continent_selected: '1.Description'!$Q$8
Name CoolTemperate: defo!$C$9:$C$18
Name CoolTemperate2: affo!$C$8:$C$17
Name country_selected: '1.Description'!$Q$9
Name EF_DIRECT_N2O_manure_mngt_cattle_poultry_pigs_titles: IPCC!$A$3065:$P$3065
Name EF_DIRECT_N2O_manure_mngt_Sheeps_others_titles: IPCC!$A$3082:$P$3082
Name eq_agrof_systems: OFFSET(list!$F$73, 1, MATCH(clim_moist, list!$F$73:$O$73,0)-1,COUNTA(OFFSET(list!$F$73, 1,MATCH(clim_moist, list!$F$73:$O$73,0)-1,10,1)),1)
Name equation: INDEX((TabBoreal[Boreal],Tabcooltemp[Cool Temperate],TabTrop[Tropical],TabTrMon[Tropical Montane],TabWarm[Warm Temperate]),,,MATCH(climate, list!$F$21:$J$21,0))
Name Error_Message: '3.Cropland'!$R$37
Name fluxesbalance: Graph!$H$29:INDEX(Graph!$H$29:$H$40,COUNT(Graph!$H$29:$H$40))
Name Frac_leach_all_categories_titles: IPCC!$A$3184:$P$3184
Name Frac_vol_dairy_cow_titles: IPCC!$A$3116:$P$3116
Name Frac_vol_Other_Animal_titles: IPCC!$A$3167:$P$3167
Name Frac_vol_Other_Cattle_titles: IPCC!$A$3150:$P$3150

Sheet 0.Start
B1: EX-ACT version 9 is based on the 2019 Refinement to the 2006 IPCC Guidelines for National Greenhouse Gas Inventories, their 2013 Supplement for Wetlands, as well as on FAOSTAT, UNFCCC, IHH, FEUD and other relevant scientific sources.
AD4: version 9.4.
B45: EX-ACT is a designed to support decision makers within the governments, private sector and civil society organizations to calculate greenhouse gas emissions using IPCC methdoologies. EX-ACT can be used in the project (or programme) design phase as well as for on-going and ex-post evaluations of interventions in agriculture (the AFOLU sector, fisheries, aquaculture, inputs and infrastructure).
B46: EX-ACT v9 has been developped by FAO's Agrifood Economics Division with the support of the World Bank and Agence Française de Développement.
B47: Website: | C47: http://www.fao.org/tc/exact/ex-act-home/en/
B48: Contact: | C48: EX-ACT@fao.org
B51: DISCLAIMER FAO declines all responsibility for errors or deficiencies in the database or software or in the documentation accompanying it, for program maintenance and upgrading as well as for any damage that may arise from them. FAO also declines any responsibility for updating the data and assumes no responsibility for errors and omissions in the data provided. Users are, however, kindly asked to report any errors or deficiencies in this product to FAO.
B52: The choices of calculation made in this tool are those of the author(s) and do not necessarily reflect the views and choices of the Food and Agriculture Organization of the United Nations.
B54: © FAO (2021) FAO encourages the use, reproduction and dissemination of material in this product. Except where otherwise indicated, material may be copied, downloaded and printed for private study, research and teaching purposes, or for use in non-commercial products or services, provided that appropriate acknowledgement of FAO as the source and copyright holder is given and that FAO’s endorsement of users’ views, products or services is not implied in any way. All requests for translation and adaptation rights, and for resale and other commercial use rights should be made via www.fao.org/contact-us/licence-request or addressed to copyright@fao.org
B59: Terms of Use for the EX-ACT: Ex-Ante Carbon-balance Tool
B60: General Provisions
B61: To support efforts towards forest monitoring, the Food and Agriculture Organization of the United Nations (FAO) has developed the EX-ACT: Ex-Ante Carbon-balance Tool to help countries identify capacity gaps and weaknesses and address their real needs in a targeted manner.
B62: The EX-ACT: Ex-Ante Carbon-balance Tool is excel-based.
B63: The Ex-Ante Carbon-balance Tool (EX-ACT) is an appraisal system developed by FAO providing estimates of the impact of agriculture and forestry development projects, programmes and policies on the carbon-balance.
B64: The carbon-balance is defined as the net balance from all greenhouse gases (GHGs) expressed in CO2 equivalent that were emitted or sequestered due to project implementation as compared to a business-as-usual scenario.
B65: EX-ACT is a land-based accounting system, estimating C stock changes (i.e. emissions or sinks of CO2) as well as GHG emissions per unit of land, expressed in equivalent tonnes of CO2 per hectare and year. The tool helps project designers to estimate and prioritize project activities with high benefits in economic and climate change mitigation terms. The amount of GHG mitigation may also be used as part of economic analyses as well as for the application for additional project funds.
B66: EX-ACT can be applied on a wide range of development projects from all Agriculture, Forestry and Other Land Use (AFOLU) sub-sectors, including besides others projects on climate change mitigation, sustainable land management, watershed development, production intensification, food security, livestock, forest management or land use change. Furthermore, it is cost effective, requires a comparatively small amount of data, and has resources (tables, maps) which can help find the required information. While EX-ACT is mostly used at project level it may easily be up scaled to the programme/sector level and can also be used for policy analysis.
B67: 1. By using the EX-ACT: Ex-Ante Carbon-balance Tool (hereinafter referred to as the “Tool”), you acknowledge and accept to be bound by these Terms of Use, and the FAO’s Terms and Conditions for use of its website Tool. If the end users do not agree to these Terms of Use, they should not use the Tool. In the event of a conflict or inconsistency between these Terms of Use and FAO’s Terms and Conditions for use of its website, the present Terms of Use shall prevail.
... B105: 19. Nothing contained in or related to these Terms and Conditions shall be deemed a waiver, express or implied, of the privileges and immunities of FAO, or as its acceptance of the jurisdiction of the courts of any country over disputes arising out of these Terms of Use or documents or arrangements related thereto.

Sheet 1.Description
D4: =Languages!B31 -> 1. DESCRIPTION
D7: =Languages!B32 -> 1.1 Project description | N7: =Languages!B42 -> 1.2 Project site and duration | Z7: =Languages!B56 -> Choose a language
D8: =Languages!B34 -> User Name | N8: =Languages!B43 -> Continent | Q8: Europe
D9: =Languages!B35 -> Date | N9: =Languages!B44 -> Country | Q9: Spain | AA9: English
D10: =Languages!B36 -> Project name | N10: =Languages!B45 -> Climate | Q10: Warm Temperate
D11: =Languages!B37 -> Project code | N11: =Languages!B46 -> Moisture | Q11: Dry
D12: =Languages!B38 -> Project cost (in USD) | N12: =Languages!B47 -> Soil Type | Q12: High activity clay soils
D13: =Languages!B39 -> Funding agency | N13: =Languages!B48 -> Project duration (in years) | S13: =Languages!B49 -> Implementation Phase | T13: 5
D14: =Languages!B40 -> Executing agency | S14: =Languages!B50 -> Capitalization Phase | T14: 10
D15: =Languages!B41 -> Project status | G15: Please select | S15: =Languages!B51 -> Total Duration of Accounting | T15: =time+time_cap -> 15
D16: if other, please specify | N16: Please ensure the MAT is > 18C and the elevation> 1000m.
L17: Organic soil should be analyzed directly in the "Inland Wetlands" module. Please refrain from analysing activities on organic soils in other modules
C22: =Languages!B53 -> 1.3 Global warming potential | O22: =Languages!B52 -> 1.4 Reference soil organic carbon stock
R23: tC/ha
D24: =Languages!B54 -> Source: | E24: 100 yr AR5 w/out CC feedback | I24: Tier 2 | R24: =Languages!B55 -> Default | S24: Tier 2
D25: CO2 | G25: =IF($E$24="please select","",1) -> 1 | P25: SOCref | R25: =IFERROR(INDEX(IPCC!$B$39:$I$49,MATCH(clim_moist,IPCC!$A$39:$A$49,0),MATCH(soil,IPCC!$B$38:$I$38,0)),"") -> 24
D26: CH4 | G26: =IF($E$24="please select","",IF($E$24="100 yr SAR", 21, IF($E$24="100 yr AR4", 25, IF($E$24="100 yr AR5 with CC feedback", 34, IF($E$24="100 yr AR5 w/out CC feedback", 28, IF($E$24="100 yr AR6", 27.2, IF($E$24="OTHER (TIER 2)", I26,""))))))) -> 28
D27: N2O | G27: =IF($E$24="please select","",IF($E$24="100 yr SAR", 310, IF($E$24="100 yr AR4", 298, IF($E$24="100 yr AR5 with CC feedback", 298, IF($E$24="100 yr AR5 w/out CC feedback", 265, IF($E$24="100 yr AR6", 273, IF($E$24="OTHER (TIER 2)", I27,""))))))) -> 265 | N27: =IF(R25="NO", "ERROR: default value does not exist for selected combination of climate, moisture and soil type", "")
D28: CH4 | E28: fossil origin | G28: =IF($E$24="please select","",IF($E$24="100 yr SAR", 21, IF($E$24="100 yr AR4", 25, IF($E$24="100 yr AR5 with CC feedback", 34, IF($E$24="100 yr AR5 w/out CC feedback", 28, IF($E$24="100 yr AR6", 29.8, IF($E$24="OTHER (TIER 2)", I26,""))))))) -> 28
D29: =IF(OR(methane=0,Nitrous=0), "Please fill the GWP for methane and nitroux oxyde before proceeding","")

Sheet defo
A3: 2.1 Deforestation
A7: IPCC forest classes stratified by climate | G7: No | H7: Forest classes per IPCC climate region | I7: AGB default | J7: AGB default | K7: AGB tier 2 | L7: BGB | M7: BGB default | N7: BGB tier 2 | O7: Litter | P7: Litter default | Q7: Dead Wood | R7: DW Tier 2 | S7: SOC(0-T) | T7: SOC Tier 2 | U7: Flu | V7: Flu tier 2
A8: Tropical | B8: WarmTemperate | C8: CoolTemperate | D8: Boreal | E8: TropicalMontane | H8: =climate2 -> WarmTemperate | I8: t d.m./ha | J8: t C/ha | K8: tC/ha | L8: t d.m./ha | M8: t C/ha | N8: tC/ha | O8: t C/ha | P8: tC/ha | Q8: t C/ha | R8: tC/ha | S8: tC/ha | T8: tC/ha
A9: Tropical rainforest | B9: Subtropical humid forest | C9: Temperate oceanic forest | D9: Boreal coniferous forest | E9: Tropical mountain systems | G9: 1 | H9: =B23 -> Please select | I9: =IF(H9="Please select",0,IF(H9="Mangrove Forest",VLOOKUP(clim_moist,IPCC!$A$1502:$G$1510,2,FALSE),INDEX(IPCC!$B$590:$AK$606,MATCH(continent_selected,IPCC!$A$590:$A$606,0),MATCH(H9,IPCC!$B$590:$AK$590,0)))) -> 0 | J9: =IF(H9="Please select",0,IF(H9="Mangrove Forest",$I9*0.451,$I9*0.47)) -> 0 | K9: =IF('2.LUC'!$AT11="",'2.LUC'!$AS11,'2.LUC'!$AT11) -> 0 | L9: =IF(H9 = "Please select",0, IF(H9="Mangrove Forest",VLOOKUP(clim_moist,IPCC!$A$1502:$G$1511,6,FALSE),IF(OR(I9<=125,I9<=75),INDEX(IPCC!$B$618:$AI$633,MATCH(continent_selected,IPCC!$A$618:$A$633,0),MATCH(H9,IPCC!$B$616:$AI$616,0)),(IF(OR(I9>125,I9>75),INDEX(IPCC!$AJ$616:$BS$633,MATCH(continent_selected,IPCC!$A$616:$A$633,0),MATCH(H9,IPCC!$AJ$616:$BS$616,0)),""))))*I9) -> 0 | M9: =IF(H9="Please select",0,IF(H9="Mangrove Forest",L9*0.451,L9*0.47)) -> 0 | N9: =IF('2.LUC'!AW11="",'2.LUC'!AV11,'2.LUC'!AW11) -> 0 | O9: =IF(H9 = "Please select", 0, IF(H9 = "Mangrove Forest", VLOOKUP(clim_moist, IPCC!$A$1502:$J$1511, 8, FALSE),VLOOKUP(H9, IPCC!$A$643:$B$677, 2, FALSE))) -> 0 | P9: =IF('2.LUC'!$AZ11="",'2.LUC'!$AY11,'2.LUC'!$AZ11) -> 0 | Q9: =IF(H9 = "Please select", 0, IF(H9= "Mangrove Forest", VLOOKUP(clim_moist, IPCC!$A$1502:$J$1511, 9, FALSE), VLOOKUP(H9, IPCC!$A$643:$C$677, 3, FALSE))) -> 0 | R9: =IF('2.LUC'!$BC11="",'2.LUC'!$BB11,'2.LUC'!$BC11) -> 0 | S9: ='2.LUC'!BE11 -> 0 | T9: =IF('2.LUC'!$BF11="",S9,'2.LUC'!$BF11) -> 0 | U9: =IF(J9= "Please select", 0, INDEX(IPCC!$B$852:$X$863,MATCH(clim_moist,IPCC!$A$852:$A$863,0),MATCH("Forest land",IPCC!$B$852:$X$852,0))) -> 1 | V9: =IF('2.LUC'!$BI11="",'2.LUC'!$BH11,'2.LUC'!$BI11) -> 1
A10: Tropical moist deciduous forest | B10: Subtropical dry forest | C10: Temperate continental forest | D10: Boreal tundra woodland | E10: Planted Tropical mountain systems | G10: 2 | H10: =B24 -> Please select | I10: =IF(H10="Please select",0,IF(H10="Mangrove Forest",VLOOKUP(clim_moist,IPCC!$A$1502:$G$1510,2,FALSE),INDEX(IPCC!$B$590:$AK$606,MATCH(continent_selected,IPCC!$A$590:$A$606,0),MATCH(H10,IPCC!$B$590:$AK$590,0)))) -> 0 | J10: =IF(H10="Please select",0,IF(H10="Mangrove Forest",$I10*0.451,$I10*0.47)) -> 0 | K10: =IF('2.LUC'!$AT12="",'2.LUC'!$AS12,'2.LUC'!$AT12) -> 0 | L10: =IF(H10 = "Please select",0, IF(H10="Mangrove Forest",VLOOKUP(clim_moist,IPCC!$A$1502:$G$1511,6,FALSE),IF(OR(I10<=125,I10<=75),INDEX(IPCC!$B$618:$AI$633,MATCH(continent_selected,IPCC!$A$618:$A$633,0),MATCH(H10,IPCC!$B$616:$AI$616,0)),(IF(OR(I10>125,I10>75),INDEX(IPCC!$AJ$616:$BS$633,MATCH(continent_selected,IPCC!$A$616:$A$633,0),MATCH(H10,IPCC!$AJ$616:$BS$616,0)),""))))*I10) -> 0 | M10: =IF(H10="Please select",0,IF(H10="Mangrove Forest",L10*0.451,L10*0.47)) -> 0 | N10: =IF('2.LUC'!AW12="",'2.LUC'!AV12,'2.LUC'!AW12) -> 0 | O10: =IF(H10 = "Please select", 0, IF(H10 = "Mangrove Forest", VLOOKUP(clim_moist, IPCC!$A$1502:$J$1511, 8, FALSE),VLOOKUP(H10, IPCC!$A$643:$B$677, 2, FALSE))) -> 0 | P10: =IF('2.LUC'!$AZ12="",'2.LUC'!$AY12,'2.LUC'!$AZ12) -> 0 | Q10: =IF(H10 = "Please select", 0, IF(H10= "Mangrove Forest", VLOOKUP(clim_moist, IPCC!$A$1502:$J$1511, 9, FALSE), VLOOKUP(H10, IPCC!$A$643:$C$677, 3, FALSE))) -> 0 | R10: =IF('2.LUC'!$BC12="",'2.LUC'!$BB12,'2.LUC'!$BC12) -> 0 | S10: ='2.LUC'!BE12 -> 0 | T10: =IF('2.LUC'!$BF12="",S10,'2.LUC'!$BF12) -> 0 | U10: =IF(J10= "Please select", 0, INDEX(IPCC!$B$852:$X$863,MATCH(clim_moist,IPCC!$A$852:$A$863,0),MATCH("Forest land",IPCC!$B$852:$X$852,0))) -> 1 | V10: =IF('2.LUC'!$BI12="",'2.LUC'!$BH12,'2.LUC'!$BI12) -> 1
A11: Tropical dry forest | B11: Subtropical steppe | C11: Temperate mountain systems | D11: Boreal mountain systems | G11: 3 | H11: =B25 -> Please select | I11: =IF(H11="Please select",0,IF(H11="Mangrove Forest",VLOOKUP(clim_moist,IPCC!$A$1502:$G$1510,2,FALSE),INDEX(IPCC!$B$590:$AK$606,MATCH(continent_selected,IPCC!$A$590:$A$606,0),MATCH(H11,IPCC!$B$590:$AK$590,0)))) -> 0 | J11: =IF(H11="Please select",0,IF(H11="Mangrove Forest",$I11*0.451,$I11*0.47)) -> 0 | K11: =IF('2.LUC'!$AT13="",'2.LUC'!$AS13,'2.LUC'!$AT13) -> 0 | L11: =IF(H11 = "Please select",0, IF(H11="Mangrove Forest",VLOOKUP(clim_moist,IPCC!$A$1502:$G$1511,6,FALSE),IF(OR(I11<=125,I11<=75),INDEX(IPCC!$B$618:$AI$633,MATCH(continent_selected,IPCC!$A$618:$A$633,0),MATCH(H11,IPCC!$B$616:$AI$616,0)),(IF(OR(I11>125,I11>75),INDEX(IPCC!$AJ$616:$BS$633,MATCH(continent_selected,IPCC!$A$616:$A$633,0),MATCH(H11,IPCC!$AJ$616:$BS$616,0)),""))))*I11) -> 0 | M11: =IF(H11="Please select",0,IF(H11="Mangrove Forest",L11*0.451,L11*0.47)) -> 0 | N11: =IF('2.LUC'!AW13="",'2.LUC'!AV13,'2.LUC'!AW13) -> 0 | O11: =IF(H11 = "Please select", 0, IF(H11 = "Mangrove Forest", VLOOKUP(clim_moist, IPCC!$A$1502:$J$1511, 8, FALSE),VLOOKUP(H11, IPCC!$A$643:$B$677, 2, FALSE))) -> 0 | P11: =IF('2.LUC'!$AZ13="",'2.LUC'!$AY13,'2.LUC'!$AZ13) -> 0 | Q11: =IF(H11 = "Please select", 0, IF(H11= "Mangrove Forest", VLOOKUP(clim_moist, IPCC!$A$1502:$J$1511, 9, FALSE), VLOOKUP(H11, IPCC!$A$643:$C$677, 3, FALSE))) -> 0 | R11: =IF('2.LUC'!$BC13="",'2.LUC'!$BB13,'2.LUC'!$BC13) -> 0 | S11: ='2.LUC'!BE13 -> 0 | T11: =IF('2.LUC'!$BF13="",S11,'2.LUC'!$BF13) -> 0 | U11: =IF(J11= "Please select", 0, INDEX(IPCC!$B$852:$X$863,MATCH(clim_moist,IPCC!$A$852:$A$863,0),MATCH("Forest land",IPCC!$B$852:$X$852,0))) -> 1 | V11: =IF('2.LUC'!$BI13="",'2.LUC'!$BH13,'2.LUC'!$BI13) -> 1
A12: Tropical shrubland | B12: Subtropical mountain systems | C12: Temperate desert | D12: Planted Boreal coniferous forest | G12: 4 | H12: =B26 -> Please select | I12: =IF(H12="Please select",0,IF(H12="Mangrove Forest",VLOOKUP(clim_moist,IPCC!$A$1502:$G$1510,2,FALSE),INDEX(IPCC!$B$590:$AK$606,MATCH(continent_selected,IPCC!$A$590:$A$606,0),MATCH(H12,IPCC!$B$590:$AK$590,0)))) -> 0 | J12: =IF(H12="Please select",0,IF(H12="Mangrove Forest",$I12*0.451,$I12*0.47)) -> 0 | K12: =IF('2.LUC'!$AT14="",'2.LUC'!$AS14,'2.LUC'!$AT14) -> 0 | L12: =IF(H12 = "Please select",0, IF(H12="Mangrove Forest",VLOOKUP(clim_moist,IPCC!$A$1502:$G$1511,6,FALSE),IF(OR(I12<=125,I12<=75),INDEX(IPCC!$B$618:$AI$633,MATCH(continent_selected,IPCC!$A$618:$A$633,0),MATCH(H12,IPCC!$B$616:$AI$616,0)),(IF(OR(I12>125,I12>75),INDEX(IPCC!$AJ$616:$BS$633,MATCH(continent_selected,IPCC!$A$616:$A$633,0),MATCH(H12,IPCC!$AJ$616:$BS$616,0)),""))))*I12) -> 0 | M12: =IF(H12="Please select",0,IF(H12="Mangrove Forest",L12*0.451,L12*0.47)) -> 0 | N12: =IF('2.LUC'!AW14="",'2.LUC'!AV14,'2.LUC'!AW14) -> 0 | O12: =IF(H12 = "Please select", 0, IF(H12 = "Mangrove Forest", VLOOKUP(clim_moist, IPCC!$A$1502:$J$1511, 8, FALSE),VLOOKUP(H12, IPCC!$A$643:$B$677, 2, FALSE))) -> 0 | P12: =IF('2.LUC'!$AZ14="",'2.LUC'!$AY14,'2.LUC'!$AZ14) -> 0 | Q12: =IF(H12 = "Please select", 0, IF(H12= "Mangrove Forest", VLOOKUP(clim_moist, IPCC!$A$1502:$J$1511, 9, FALSE), VLOOKUP(H12, IPCC!$A$643:$C$677, 3, FALSE))) -> 0 | R12: =IF('2.LUC'!$BC14="",'2.LUC'!$BB14,'2.LUC'!$BC14) -> 0 | S12: ='2.LUC'!BE14 -> 0 | T12: =IF('2.LUC'!$BF14="",S12,'2.LUC'!$BF14) -> 0 | U12: =IF(J12= "Please select", 0, INDEX(IPCC!$B$852:$X$863,MATCH(clim_moist,IPCC!$A$852:$A$863,0),MATCH("Forest land",IPCC!$B$852:$X$852,0))) -> 1 | V12: =IF('2.LUC'!$BI14="",'2.LUC'!$BH14,'2.LUC'!$BI14) -> 1
A13: Mangrove Forest | B13: Planted Subtropical humid forest | C13: Temperate steppe | D13: Planted Boreal tundra woodland | G13: 5 | H13: =B27 -> Please select | I13: =IF(H13="Please select",0,IF(H13="Mangrove Forest",VLOOKUP(clim_moist,IPCC!$A$1502:$G$1510,2,FALSE),INDEX(IPCC!$B$590:$AK$606,MATCH(continent_selected,IPCC!$A$590:$A$606,0),MATCH(H13,IPCC!$B$590:$AK$590,0)))) -> 0 | J13: =IF(H13="Please select",0,IF(H13="Mangrove Forest",$I13*0.451,$I13*0.47)) -> 0 | K13: =IF('2.LUC'!$AT15="",'2.LUC'!$AS15,'2.LUC'!$AT15) -> 0 | L13: =IF(H13 = "Please select",0, IF(H13="Mangrove Forest",VLOOKUP(clim_moist,IPCC!$A$1502:$G$1511,6,FALSE),IF(OR(I13<=125,I13<=75),INDEX(IPCC!$B$618:$AI$633,MATCH(continent_selected,IPCC!$A$618:$A$633,0),MATCH(H13,IPCC!$B$616:$AI$616,0)),(IF(OR(I13>125,I13>75),INDEX(IPCC!$AJ$616:$BS$633,MATCH(continent_selected,IPCC!$A$616:$A$633,0),MATCH(H13,IPCC!$AJ$616:$BS$616,0)),""))))*I13) -> 0 | M13: =IF(H13="Please select",0,IF(H13="Mangrove Forest",L13*0.451,L13*0.47)) -> 0 | N13: =IF('2.LUC'!AW15="",'2.LUC'!AV15,'2.LUC'!AW15) -> 0 | O13: =IF(H13 = "Please select", 0, IF(H13 = "Mangrove Forest", VLOOKUP(clim_moist, IPCC!$A$1502:$J$1511, 8, FALSE),VLOOKUP(H13, IPCC!$A$643:$B$677, 2, FALSE))) -> 0 | P13: =IF('2.LUC'!$AZ15="",'2.LUC'!$AY15,'2.LUC'!$AZ15) -> 0 | Q13: =IF(H13 = "Please select", 0, IF(H13= "Mangrove Forest", VLOOKUP(clim_moist, IPCC!$A$1502:$J$1511, 9, FALSE), VLOOKUP(H13, IPCC!$A$643:$C$677, 3, FALSE))) -> 0 | R13: =IF('2.LUC'!$BC15="",'2.LUC'!$BB15,'2.LUC'!$BC15) -> 0 | S13: ='2.LUC'!BE15 -> 0 | T13: =IF('2.LUC'!$BF15="",S13,'2.LUC'!$BF15) -> 0 | U13: =IF(J13= "Please select", 0, INDEX(IPCC!$B$852:$X$863,MATCH(clim_moist,IPCC!$A$852:$A$863,0),MATCH("Forest land",IPCC!$B$852:$X$852,0))) -> 1 | V13: =IF('2.LUC'!$BI15="",'2.LUC'!$BH15,'2.LUC'!$BI15) -> 1
A14: Planted Tropical rainforest | B14: Planted Subtropical dry forest | C14: Planted Temperate oceanic forest | D14: Planted Boreal mountain systems | G14: 6 | H14: =B28 -> Please select | I14: =IF(H14="Please select",0,IF(H14="Mangrove Forest",VLOOKUP(clim_moist,IPCC!$A$1502:$G$1510,2,FALSE),INDEX(IPCC!$B$590:$AK$606,MATCH(continent_selected,IPCC!$A$590:$A$606,0),MATCH(H14,IPCC!$B$590:$AK$590,0)))) -> 0 | J14: =IF(H14="Please select",0,IF(H14="Mangrove Forest",$I14*0.451,$I14*0.47)) -> 0 | K14: =IF('2.LUC'!$AT16="",'2.LUC'!$AS16,'2.LUC'!$AT16) -> 0 | L14: =IF(H14 = "Please select",0, IF(H14="Mangrove Forest",VLOOKUP(clim_moist,IPCC!$A$1502:$G$1511,6,FALSE),IF(OR(I14<=125,I14<=75),INDEX(IPCC!$B$618:$AI$633,MATCH(continent_selected,IPCC!$A$618:$A$633,0),MATCH(H14,IPCC!$B$616:$AI$616,0)),(IF(OR(I14>125,I14>75),INDEX(IPCC!$AJ$616:$BS$633,MATCH(continent_selected,IPCC!$A$616:$A$633,0),MATCH(H14,IPCC!$AJ$616:$BS$616,0)),""))))*I14) -> 0 | M14: =IF(H14="Please select",0,IF(H14="Mangrove Forest",L14*0.451,L14*0.47)) -> 0 | N14: =IF('2.LUC'!AW16="",'2.LUC'!AV16,'2.LUC'!AW16) -> 0 | O14: =IF(H14 = "Please select", 0, IF(H14 = "Mangrove Forest", VLOOKUP(clim_moist, IPCC!$A$1502:$J$1511, 8, FALSE),VLOOKUP(H14, IPCC!$A$643:$B$677, 2, FALSE))) -> 0 | P14: =IF('2.LUC'!$AZ16="",'2.LUC'!$AY16,'2.LUC'!$AZ16) -> 0 | Q14: =IF(H14 = "Please select", 0, IF(H14= "Mangrove Forest", VLOOKUP(clim_moist, IPCC!$A$1502:$J$1511, 9, FALSE), VLOOKUP(H14, IPCC!$A$643:$C$677, 3, FALSE))) -> 0 | R14: =IF('2.LUC'!$BC16="",'2.LUC'!$BB16,'2.LUC'!$BC16) -> 0 | S14: ='2.LUC'!BE16 -> 0 | T14: =IF('2.LUC'!$BF16="",S14,'2.LUC'!$BF16) -> 0 | U14: =IF(J14= "Please select", 0, INDEX(IPCC!$B$852:$X$863,MATCH(clim_moist,IPCC!$A$852:$A$863,0),MATCH("Forest land",IPCC!$B$852:$X$852,0))) -> 1 | V14: =IF('2.LUC'!$BI16="",'2.LUC'!$BH16,'2.LUC'!$BI16) -> 1
A15: Planted Tropical moist deciduous forest | B15: Planted Subtropical steppe | C15: Planted Temperate continental forest | G15: 7 | H15: =B29 -> Please select | I15: =IF(H15="Please select",0,IF(H15="Mangrove Forest",VLOOKUP(clim_moist,IPCC!$A$1502:$G$1510,2,FALSE),INDEX(IPCC!$B$590:$AK$606,MATCH(continent_selected,IPCC!$A$590:$A$606,0),MATCH(H15,IPCC!$B$590:$AK$590,0)))) -> 0 | J15: =IF(H15="Please select",0,IF(H15="Mangrove Forest",$I15*0.451,$I15*0.47)) -> 0 | K15: =IF('2.LUC'!$AT17="",'2.LUC'!$AS17,'2.LUC'!$AT17) -> 0 | L15: =IF(H15 = "Please select",0, IF(H15="Mangrove Forest",VLOOKUP(clim_moist,IPCC!$A$1502:$G$1511,6,FALSE),IF(OR(I15<=125,I15<=75),INDEX(IPCC!$B$618:$AI$633,MATCH(continent_selected,IPCC!$A$618:$A$633,0),MATCH(H15,IPCC!$B$616:$AI$616,0)),(IF(OR(I15>125,I15>75),INDEX(IPCC!$AJ$616:$BS$633,MATCH(continent_selected,IPCC!$A$616:$A$633,0),MATCH(H15,IPCC!$AJ$616:$BS$616,0)),""))))*I15) -> 0 | M15: =IF(H15="Please select",0,IF(H15="Mangrove Forest",L15*0.451,L15*0.47)) -> 0 | N15: =IF('2.LUC'!AW17="",'2.LUC'!AV17,'2.LUC'!AW17) -> 0 | O15: =IF(H15 = "Please select", 0, IF(H15 = "Mangrove Forest", VLOOKUP(clim_moist, IPCC!$A$1502:$J$1511, 8, FALSE),VLOOKUP(H15, IPCC!$A$643:$B$677, 2, FALSE))) -> 0 | P15: =IF('2.LUC'!$AZ17="",'2.LUC'!$AY17,'2.LUC'!$AZ17) -> 0 | Q15: =IF(H15 = "Please select", 0, IF(H15= "Mangrove Forest", VLOOKUP(clim_moist, IPCC!$A$1502:$J$1511, 9, FALSE), VLOOKUP(H15, IPCC!$A$643:$C$677, 3, FALSE))) -> 0 | R15: =IF('2.LUC'!$BC17="",'2.LUC'!$BB17,'2.LUC'!$BC17) -> 0 | S15: ='2.LUC'!BE17 -> 0 | T15: =IF('2.LUC'!$BF17="",S15,'2.LUC'!$BF17) -> 0 | U15: =IF(J15= "Please select", 0, INDEX(IPCC!$B$852:$X$863,MATCH(clim_moist,IPCC!$A$852:$A$863,0),MATCH("Forest land",IPCC!$B$852:$X$852,0))) -> 1 | V15: =IF('2.LUC'!$BI17="",'2.LUC'!$BH17,'2.LUC'!$BI17) -> 1
A16: Planted Tropical dry forest | B16: Planted Subtropical mountain systems | C16: Planted Temperate mountain systems | G16: 8 | H16: =B30 -> Please select | I16: =IF(H16="Please select",0,IF(H16="Mangrove Forest",VLOOKUP(clim_moist,IPCC!$A$1502:$G$1510,2,FALSE),INDEX(IPCC!$B$590:$AK$606,MATCH(continent_selected,IPCC!$A$590:$A$606,0),MATCH(H16,IPCC!$B$590:$AK$590,0)))) -> 0 | J16: =IF(H16="Please select",0,IF(H16="Mangrove Forest",$I16*0.451,$I16*0.47)) -> 0 | K16: =IF('2.LUC'!$AT18="",'2.LUC'!$AS18,'2.LUC'!$AT18) -> 0 | L16: =IF(H16 = "Please select",0, IF(H16="Mangrove Forest",VLOOKUP(clim_moist,IPCC!$A$1502:$G$1511,6,FALSE),IF(OR(I16<=125,I16<=75),INDEX(IPCC!$B$618:$AI$633,MATCH(continent_selected,IPCC!$A$618:$A$633,0),MATCH(H16,IPCC!$B$616:$AI$616,0)),(IF(OR(I16>125,I16>75),INDEX(IPCC!$AJ$616:$BS$633,MATCH(continent_selected,IPCC!$A$616:$A$633,0),MATCH(H16,IPCC!$AJ$616:$BS$616,0)),""))))*I16) -> 0 | M16: =IF(H16="Please select",0,IF(H16="Mangrove Forest",L16*0.451,L16*0.47)) -> 0 | N16: =IF('2.LUC'!AW18="",'2.LUC'!AV18,'2.LUC'!AW18) -> 0 | O16: =IF(H16 = "Please select", 0, IF(H16 = "Mangrove Forest", VLOOKUP(clim_moist, IPCC!$A$1502:$J$1511, 8, FALSE),VLOOKUP(H16, IPCC!$A$643:$B$677, 2, FALSE))) -> 0 | P16: =IF('2.LUC'!$AZ18="",'2.LUC'!$AY18,'2.LUC'!$AZ18) -> 0 | Q16: =IF(H16 = "Please select", 0, IF(H16= "Mangrove Forest", VLOOKUP(clim_moist, IPCC!$A$1502:$J$1511, 9, FALSE), VLOOKUP(H16, IPCC!$A$643:$C$677, 3, FALSE))) -> 0 | R16: =IF('2.LUC'!$BC18="",'2.LUC'!$BB18,'2.LUC'!$BC18) -> 0 | S16: ='2.LUC'!BE18 -> 0 | T16: =IF('2.LUC'!$BF18="",S16,'2.LUC'!$BF18) -> 0 | U16: =IF(J16= "Please select", 0, INDEX(IPCC!$B$852:$X$863,MATCH(clim_moist,IPCC!$A$852:$A$863,0),MATCH("Forest land",IPCC!$B$852:$X$852,0))) -> 1 | V16: =IF('2.LUC'!$BI18="",'2.LUC'!$BH18,'2.LUC'!$BI18) -> 1
A17: Planted Tropical shrubland | B17: Mangrove Forest | C17: Planted Temperate desert
C18: Planted Temperate steppe
F20: Combustion factor (Cf) | G20: FINAL LAND USE | J20: BIOMASS FINAL | K20: BIOMASS FOREST | O20: Soil | S20: Fire | T20: Fire | U20: Fire | V20: SOM mineralization due to LUC | W20: soil N2O | X20: CH4 & N2O | Z20: CH4 fire | AB20: N2O fire | AD20: N2O SOM
A21: Name | B21: Vegetation Type | C21: HWP before | E21: Fire use | F21: the fraction (%) | G21: Final land use | H21: Final agroforestry | I21: incl. agroforestry systems | J21: After 1 yr of growth of Final LU | K21: AGB+BGB | M21: DOM (DW + litter) | O21: FLU | P21: FLU tier 2 | Q21: ΔC Mineral | R21: ΔC Mineral | S21: MB = AGB - HWP | T21: CH4 | U21: N2O | V21: FSOM - kg N mineralized | Z21: Without | AA21: With | AB21: Without | AC21: With | AD21: Without | AE21: With | AG21: Fire occurrence
B22: deforested | C22: t DM/ha | D22: t C exported/ha | E22: yes/no | F22: combusted | G22: after deforestation | H22: After deforestation | J22: tC/ha | K22: t C/ha | L22: t CO2/ha | M22: t C/ha | N22: t CO2/ha | O22: ( - ) | P22: ( - ) | Q22: tC/ha | R22: tCO2/ha/yr | S22: t dm/ha | T22: kgCH4 | U22: kgN2O | V22: kg N /year | W22: kg | X22: tCO2 eq | Z22: tCO2 | AA22: tCO2 | AB22: tCO2 | AC22: tCO2 | AD22: tCO2 | AE22: tCO2 | AG22: START | AH22: WITHOUT | AI22: WITH
A23: Deforestation 1 | B23: ='2.LUC'!$C11 -> Please select | C23: ='2.LUC'!$E11 -> 0 | D23: =IF('2.LUC'!$C11="Please select",0,IF(C23>VLOOKUP($B23,defo!$H$9:$K$16,2,FALSE),VLOOKUP($B23,defo!$H$9:$K$16,2,FALSE),'2.LUC'!$E11))*IF(B23="Mangrove Forest",0.451, 0.47) -> 0 | E23: ='2.LUC'!$G11 -> NO | F23: =IF($B23<> "Please select", IF($E23="YES", VLOOKUP($B23, IPCC!$A$871:$B$906, 2, FALSE),0), 0) -> 0 | G23: ='2.LUC'!$I11 -> Please select | H23: ='2.LUC'!$K11 -> Please select | I23: =IF('2.LUC'!$K11 <> "Please select", '2.LUC'!$K11, IF('2.LUC'!$I11<>"Agroforestry", '2.LUC'!$I11, "Agroforestry - default")) -> Please select | J23: =IF('2.LUC'!$I11 <> "Please select", IF('2.LUC'!BP11=0, INDEX(IPCC!$D$686:$Y$845,MATCH(clim_moist_cont,IPCC!$C$686:$C$845,0),MATCH($I23,IPCC!$D$682:$Y$682,0)), '2.LUC'!BP11), 0) -> 0 | K23: =IF('2.LUC'!$C11<>"Please select",$K9-$D23+$N9,0) -> 0 | L23: =K23*44/12 -> 0 | M23: =IF('2.LUC'!$C11<>"Please select",P9+R9,0) -> 0 | N23: =M23*44/12 -> 0 | O23: =IF($I23<> "Please select", INDEX(IPCC!$B$852:$W$863,MATCH(clim_moist,IPCC!$A$852:$A$863,0),MATCH($I23,IPCC!$B$852:$W$852,0)),0) -> 0 | P23: ='2.LUC'!BV11 -> 0 | Q23: =IF($I23<>"Please select",IF('2.LUC'!BS11=0, '2.LUC'!BR11*IF(OR(P23=0, P23=""),$O23, P23)-$T9*V9, '2.LUC'!BS11*IF(OR(P23=0, P23=""),$O23, P23)-$T9*V9),0) -> 0 | R23: =Q23*(-44/12)/20 -> 0 | S23: =IF($E23="NO",0,(VLOOKUP($B23,$H$9:$I$16,2,FALSE)-$C23)) -> 0 | T23: =IF($E23="YES", ($S23*VLOOKUP($B23, IPCC!$A$871:$E$906,2, FALSE)*VLOOKUP($B23, IPCC!$A$871:$E$906, 4, FALSE)), 0) -> 0 | U23: =IF($E23="YES", ($S23*VLOOKUP($B23, IPCC!$A$871:$E$906,2, FALSE)*VLOOKUP($B23, IPCC!$A$871:$E$906, 5, FALSE)), 0) -> 0 | V23: =IF($Q23>=0, 0, ((-1)*(($Q23/20*1/IPCC!$B$913)*1000))) -> 0 | W23: =IF(country_selected="Please select",0,V23*VLOOKUP(moist_type, IPCC!$B$99:$C$101, 2, FALSE)*N2O_N_conversion) -> 0 | X23: =($T23*methane+($U23+W23)*Nitrous)/1000 -> 0 | Z23: =IF($E23= "YES", $G35*$T23*methane/1000,0) -> 0 | AA23: =IF($E23= "YES", $H35*$T23*methane/1000,0) -> 0 | AB23: =$G35*$U23*Nitrous/1000 -> 0 | AC23: =$H35*$U23*Nitrous/1000 -> 0 | AD23: =$G35*$W23*Nitrous/1000 -> 0 | AE23: =$H35*$W23*Nitrous/1000 -> 0 | AG23: 0 | AH23: =IF($F23>0, $G35, 0) -> 0 | AI23: =IF($F23>0, $H35, 0) -> 0
A24: Deforestation 2 | B24: ='2.LUC'!$C12 -> Please select | C24: ='2.LUC'!$E12 -> 0 | D24: =IF('2.LUC'!$C12="Please select",0,IF(C24>VLOOKUP($B24,defo!$H$9:$K$16,2,FALSE),VLOOKUP($B24,defo!$H$9:$K$16,2,FALSE),'2.LUC'!$E12))*IF(B24="Mangrove Forest",0.451, 0.47) -> 0 | E24: ='2.LUC'!$G12 -> NO | F24: =IF($B24<> "Please select", IF($E24="YES", VLOOKUP($B24, IPCC!$A$871:$B$906, 2, FALSE),0), 0) -> 0 | G24: ='2.LUC'!$I12 -> Please select | H24: ='2.LUC'!$K12 -> Please select | I24: =IF('2.LUC'!$K12 <> "Please select", '2.LUC'!$K12, IF('2.LUC'!$I12<>"Agroforestry", '2.LUC'!$I12, "Agroforestry - default")) -> Please select | J24: =IF('2.LUC'!$I12 <> "Please select", IF('2.LUC'!BP12=0, INDEX(IPCC!$D$686:$Y$845,MATCH(clim_moist_cont,IPCC!$C$686:$C$845,0),MATCH($I24,IPCC!$D$682:$Y$682,0)), '2.LUC'!BP12), 0) -> 0 | K24: =IF('2.LUC'!$C12<>"Please select",$K10-$D24+$N10,0) -> 0 | L24: =K24*44/12 -> 0 | M24: =IF('2.LUC'!$C12<>"Please select",P10+R10,0) -> 0 | N24: =M24*44/12 -> 0 | O24: =IF($I24<> "Please select", INDEX(IPCC!$B$852:$W$863,MATCH(clim_moist,IPCC!$A$852:$A$863,0),MATCH($I24,IPCC!$B$852:$W$852,0)),0) -> 0 | P24: ='2.LUC'!BV12 -> 0 | Q24: =IF($I24<>"Please select",IF('2.LUC'!BS12=0, $T10*IF(OR(P24=0, P24=""),$O24, P24)-$T10, '2.LUC'!BS12*IF(OR(P24=0, P24=""),$O24, P24)-$T10),0) -> 0 | R24: =Q24*(-44/12)/20 -> 0 | S24: =IF($E24="NO",0,(VLOOKUP($B24,$H$9:$I$16,2,FALSE)-$C24)) -> 0 | T24: =IF($E24="YES", ($S24*VLOOKUP($B24, IPCC!$A$871:$E$906,2, FALSE)*VLOOKUP($B24, IPCC!$A$871:$E$906, 4, FALSE)), 0) -> 0 | U24: =IF($E24="YES", ($S24*VLOOKUP($B24, IPCC!$A$871:$E$906,2, FALSE)*VLOOKUP($B24, IPCC!$A$871:$E$906, 5, FALSE)), 0) -> 0 | V24: =IF($Q24>=0, 0, ((-1)*(($Q24/20*1/IPCC!$B$913)*1000))) -> 0 | W24: =IF(country_selected="Please select",0,V24*VLOOKUP(moist_type, IPCC!$B$99:$C$101, 2, FALSE)*N2O_N_conversion) -> 0 | X24: =($T24*methane+($U24+W24)*Nitrous)/1000 -> 0 | Z24: =IF($E24= "YES", $G36*$T24*methane/1000,0) -> 0 | AA24: =IF($E24= "YES", $H36*$T24*methane/1000,0) -> 0 | AB24: =$G36*$U24*Nitrous/1000 -> 0 | AC24: =$H36*$U24*Nitrous/1000 -> 0 | AD24: =$G36*$W24*Nitrous/1000 -> 0 | AE24: =$H36*$W24*Nitrous/1000 -> 0 | AG24: 0 | AH24: =IF($F24>0, $G36, 0) -> 0 | AI24: =IF($F24>0, $H36, 0) -> 0
A25: Deforestation 3 | B25: ='2.LUC'!$C13 -> Please select | C25: ='2.LUC'!$E13 -> 0 | D25: =IF('2.LUC'!$C13="Please select",0,IF(C25>VLOOKUP($B25,defo!$H$9:$K$16,2,FALSE),VLOOKUP($B25,defo!$H$9:$K$16,2,FALSE),'2.LUC'!$E13))*IF(B25="Mangrove Forest",0.451, 0.47) -> 0 | E25: ='2.LUC'!$G13 -> NO | F25: =IF($B25<> "Please select", IF($E25="YES", VLOOKUP($B25, IPCC!$A$871:$B$906, 2, FALSE),0), 0) -> 0 | G25: ='2.LUC'!$I13 -> Please select | H25: ='2.LUC'!$K13 -> Please select | I25: =IF('2.LUC'!$K13 <> "Please select", '2.LUC'!$K13, IF('2.LUC'!$I13<>"Agroforestry", '2.LUC'!$I13, "Agroforestry - default")) -> Please select | J25: =IF('2.LUC'!$I13 <> "Please select", IF('2.LUC'!BP13=0, INDEX(IPCC!$D$686:$Y$845,MATCH(clim_moist_cont,IPCC!$C$686:$C$845,0),MATCH($I25,IPCC!$D$682:$Y$682,0)), '2.LUC'!BP13), 0) -> 0 | K25: =IF('2.LUC'!$C13<>"Please select",$K11-$D25+$N11,0) -> 0 | L25: =K25*44/12 -> 0 | M25: =IF('2.LUC'!$C13<>"Please select",P11+R11,0) -> 0 | N25: =M25*44/12 -> 0 | O25: =IF($I25<> "Please select", INDEX(IPCC!$B$852:$W$863,MATCH(clim_moist,IPCC!$A$852:$A$863,0),MATCH($I25,IPCC!$B$852:$W$852,0)),0) -> 0 | P25: ='2.LUC'!BV13 -> 0 | Q25: =IF($I25<>"Please select",IF('2.LUC'!BS13=0, $T11*IF(OR(P25=0, P25=""),$O25, P25)-$T11, '2.LUC'!BS13*IF(OR(P25=0, P25=""),$O25, P25)-$T11),0) -> 0 | R25: =Q25*(-44/12)/20 -> 0 | S25: =IF($E25="NO",0,(VLOOKUP($B25,$H$9:$I$16,2,FALSE)-$C25)) -> 0 | T25: =IF($E25="YES", ($S25*VLOOKUP($B25, IPCC!$A$871:$E$906,2, FALSE)*VLOOKUP($B25, IPCC!$A$871:$E$906, 4, FALSE)), 0) -> 0 | U25: =IF($E25="YES", ($S25*VLOOKUP($B25, IPCC!$A$871:$E$906,2, FALSE)*VLOOKUP($B25, IPCC!$A$871:$E$906, 5, FALSE)), 0) -> 0 | V25: =IF($Q25>=0, 0, ((-1)*(($Q25/20*1/IPCC!$B$913)*1000))) -> 0 | W25: =IF(country_selected="Please select",0,V25*VLOOKUP(moist_type, IPCC!$B$99:$C$101, 2, FALSE)*N2O_N_conversion) -> 0 | X25: =($T25*methane+($U25+W25)*Nitrous)/1000 -> 0 | Z25: =IF($E25= "YES", $G37*$T25*methane/1000,0) -> 0 | AA25: =IF($E25= "YES", $H37*$T25*methane/1000,0) -> 0 | AB25: =$G37*$U25*Nitrous/1000 -> 0 | AC25: =$H37*$U25*Nitrous/1000 -> 0 | AD25: =$G37*$W25*Nitrous/1000 -> 0 | AE25: =$H37*$W25*Nitrous/1000 -> 0 | AG25: 0 | AH25: =IF($F25>0, $G37, 0) -> 0 | AI25: =IF($F25>0, $H37, 0) -> 0
A26: Deforestation 4 | B26: ='2.LUC'!$C14 -> Please select | C26: ='2.LUC'!$E14 -> 0 | D26: =IF('2.LUC'!$C14="Please select",0,IF(C26>VLOOKUP($B26,defo!$H$9:$K$16,2,FALSE),VLOOKUP($B26,defo!$H$9:$K$16,2,FALSE),'2.LUC'!$E14))*IF(B26="Mangrove Forest",0.451, 0.47) -> 0 | E26: ='2.LUC'!$G14 -> NO | F26: =IF($B26<> "Please select", IF($E26="YES", VLOOKUP($B26, IPCC!$A$871:$B$906, 2, FALSE),0), 0) -> 0 | G26: ='2.LUC'!$I14 -> Please select | H26: ='2.LUC'!$K14 -> Please select | I26: =IF('2.LUC'!$K14 <> "Please select", '2.LUC'!$K14, IF('2.LUC'!$I14<>"Agroforestry", '2.LUC'!$I14, "Agroforestry - default")) -> Please select | J26: =IF('2.LUC'!$I14 <> "Please select", IF('2.LUC'!BP14=0, INDEX(IPCC!$D$686:$Y$845,MATCH(clim_moist_cont,IPCC!$C$686:$C$845,0),MATCH($I26,IPCC!$D$682:$Y$682,0)), '2.LUC'!BP14), 0) -> 0 | K26: =IF('2.LUC'!$C14<>"Please select",$K12-$D26+$N12,0) -> 0 | L26: =K26*44/12 -> 0 | M26: =IF('2.LUC'!$C14<>"Please select",P12+R12,0) -> 0 | N26: =M26*44/12 -> 0 | O26: =IF($I26<> "Please select", INDEX(IPCC!$B$852:$W$863,MATCH(clim_moist,IPCC!$A$852:$A$863,0),MATCH($I26,IPCC!$B$852:$W$852,0)),0) -> 0 | P26: ='2.LUC'!BV14 -> 0 | Q26: =IF($I26<>"Please select",IF('2.LUC'!BS14=0, $T12*IF(OR(P26=0, P26=""),$O26, P26)-$T12, '2.LUC'!BS14*IF(OR(P26=0, P26=""),$O26, P26)-$T12),0) -> 0 | R26: =Q26*(-44/12)/20 -> 0 | S26: =IF($E26="NO",0,(VLOOKUP($B26,$H$9:$I$16,2,FALSE)-$C26)) -> 0 | T26: =IF($E26="YES", ($S26*VLOOKUP($B26, IPCC!$A$871:$E$906,2, FALSE)*VLOOKUP($B26, IPCC!$A$871:$E$906, 4, FALSE)), 0) -> 0 | U26: =IF($E26="YES", ($S26*VLOOKUP($B26, IPCC!$A$871:$E$906,2, FALSE)*VLOOKUP($B26, IPCC!$A$871:$E$906, 5, FALSE)), 0) -> 0 | V26: =IF($Q26>=0, 0, ((-1)*(($Q26/20*1/IPCC!$B$913)*1000))) -> 0 | W26: =IF(country_selected="Please select",0,V26*VLOOKUP(moist_type, IPCC!$B$99:$C$101, 2, FALSE)*N2O_N_conversion) -> 0 | X26: =($T26*methane+($U26+W26)*Nitrous)/1000 -> 0 | Z26: =IF($E26= "YES", $G38*$T26*methane/1000,0) -> 0 | AA26: =IF($E26= "YES", $H38*$T26*methane/1000,0) -> 0 | AB26: =$G38*$U26*Nitrous/1000 -> 0 | AC26: =$H38*$U26*Nitrous/1000 -> 0 | AD26: =$G38*$W26*Nitrous/1000 -> 0 | AE26: =$H38*$W26*Nitrous/1000 -> 0 | AG26: 0 | AH26: =IF($F26>0, $G38, 0) -> 0 | AI26: =IF($F26>0, $H38, 0) -> 0
A27: Deforestation 5 | B27: ='2.LUC'!$C15 -> Please select | C27: ='2.LUC'!$E15 -> 0 | D27: =IF('2.LUC'!$C15="Please select",0,IF(C27>VLOOKUP($B27,defo!$H$9:$K$16,2,FALSE),VLOOKUP($B27,defo!$H$9:$K$16,2,FALSE),'2.LUC'!$E15))*IF(B27="Mangrove Forest",0.451, 0.47) -> 0 | E27: ='2.LUC'!$G15 -> NO | F27: =IF($B27<> "Please select", IF($E27="YES", VLOOKUP($B27, IPCC!$A$871:$B$906, 2, FALSE),0), 0) -> 0 | G27: ='2.LUC'!$I15 -> Please select | H27: ='2.LUC'!$K15 -> Please select | I27: =IF('2.LUC'!$K15 <> "Please select", '2.LUC'!$K15, IF('2.LUC'!$I15<>"Agroforestry", '2.LUC'!$I15, "Agroforestry - default")) -> Please select | J27: =IF('2.LUC'!$I15 <> "Please select", IF('2.LUC'!BP15=0, INDEX(IPCC!$D$686:$Y$845,MATCH(clim_moist_cont,IPCC!$C$686:$C$845,0),MATCH($I27,IPCC!$D$682:$Y$682,0)), '2.LUC'!BP15), 0) -> 0 | K27: =IF('2.LUC'!$C15<>"Please select",$K13-$D27+$N13,0) -> 0 | L27: =K27*44/12 -> 0 | M27: =IF('2.LUC'!$C15<>"Please select",P13+R13,0) -> 0 | N27: =M27*44/12 -> 0 | O27: =IF($I27<> "Please select", INDEX(IPCC!$B$852:$W$863,MATCH(clim_moist,IPCC!$A$852:$A$863,0),MATCH($I27,IPCC!$B$852:$W$852,0)),0) -> 0 | P27: ='2.LUC'!BV15 -> 0 | Q27: =IF($I27<>"Please select",IF('2.LUC'!BS15=0, $T13*IF(OR(P27=0, P27=""),$O27, P27)-$T13, '2.LUC'!BS15*IF(OR(P27=0, P27=""),$O27, P27)-$T13),0) -> 0 | R27: =Q27*(-44/12)/20 -> 0 | S27: =IF($E27="NO",0,(VLOOKUP($B27,$H$9:$I$16,2,FALSE)-$C27)) -> 0 | T27: =IF($E27="YES", ($S27*VLOOKUP($B27, IPCC!$A$871:$E$906,2, FALSE)*VLOOKUP($B27, IPCC!$A$871:$E$906, 4, FALSE)), 0) -> 0 | U27: =IF($E27="YES", ($S27*VLOOKUP($B27, IPCC!$A$871:$E$906,2, FALSE)*VLOOKUP($B27, IPCC!$A$871:$E$906, 5, FALSE)), 0) -> 0 | V27: =IF($Q27>=0, 0, ((-1)*(($Q27/20*1/IPCC!$B$913)*1000))) -> 0 | W27: =IF(country_selected="Please select",0,V27*VLOOKUP(moist_type, IPCC!$B$99:$C$101, 2, FALSE)*N2O_N_conversion) -> 0 | X27: =($T27*methane+($U27+W27)*Nitrous)/1000 -> 0 | Z27: =IF($E27= "YES", $G39*$T27*methane/1000,0) -> 0 | AA27: =IF($E27= "YES", $H39*$T27*methane/1000,0) -> 0 | AB27: =$G39*$U27*Nitrous/1000 -> 0 | AC27: =$H39*$U27*Nitrous/1000 -> 0 | AD27: =$G39*$W27*Nitrous/1000 -> 0 | AE27: =$H39*$W27*Nitrous/1000 -> 0 | AG27: 0 | AH27: =IF($F27>0, $G39, 0) -> 0 | AI27: =IF($F27>0, $H39, 0) -> 0
A28: Deforestation 6 | B28: ='2.LUC'!$C16 -> Please select | C28: ='2.LUC'!$E16 -> 0 | D28: =IF('2.LUC'!$C16="Please select",0,IF(C28>VLOOKUP($B28,defo!$H$9:$K$16,2,FALSE),VLOOKUP($B28,defo!$H$9:$K$16,2,FALSE),'2.LUC'!$E16))*IF(B28="Mangrove Forest",0.451, 0.47) -> 0 | E28: ='2.LUC'!$G16 -> NO | F28: =IF($B28<> "Please select", IF($E28="YES", VLOOKUP($B28, IPCC!$A$871:$B$906, 2, FALSE),0), 0) -> 0 | G28: ='2.LUC'!$I16 -> Please select | H28: ='2.LUC'!$K16 -> Please select | I28: =IF('2.LUC'!$K16 <> "Please select", '2.LUC'!$K16, IF('2.LUC'!$I16<>"Agroforestry", '2.LUC'!$I16, "Agroforestry - default")) -> Please select | J28: =IF('2.LUC'!$I16 <> "Please select", IF('2.LUC'!BP16=0, INDEX(IPCC!$D$686:$Y$845,MATCH(clim_moist_cont,IPCC!$C$686:$C$845,0),MATCH($I28,IPCC!$D$682:$Y$682,0)), '2.LUC'!BP16), 0) -> 0 | K28: =IF('2.LUC'!$C16<>"Please select",$K14-$D28+$N14,0) -> 0 | L28: =K28*44/12 -> 0 | M28: =IF('2.LUC'!$C16<>"Please select",P14+R14,0) -> 0 | N28: =M28*44/12 -> 0 | O28: =IF($I28<> "Please select", INDEX(IPCC!$B$852:$W$863,MATCH(clim_moist,IPCC!$A$852:$A$863,0),MATCH($I28,IPCC!$B$852:$W$852,0)),0) -> 0 | P28: ='2.LUC'!BV16 -> 0 | Q28: =IF($I28<>"Please select",IF('2.LUC'!BS16=0, $T14*IF(OR(P28=0, P28=""),$O28, P28)-$T14, '2.LUC'!BS16*IF(OR(P28=0, P28=""),$O28, P28)-$T14),0) -> 0 | R28: =Q28*(-44/12)/20 -> 0 | S28: =IF($E28="NO",0,(VLOOKUP($B28,$H$9:$I$16,2,FALSE)-$C28)) -> 0 | T28: =IF($E28="YES", ($S28*VLOOKUP($B28, IPCC!$A$871:$E$906,2, FALSE)*VLOOKUP($B28, IPCC!$A$871:$E$906, 4, FALSE)), 0) -> 0 | U28: =IF($E28="YES", ($S28*VLOOKUP($B28, IPCC!$A$871:$E$906,2, FALSE)*VLOOKUP($B28, IPCC!$A$871:$E$906, 5, FALSE)), 0) -> 0 | V28: =IF($Q28>=0, 0, ((-1)*(($Q28/20*1/IPCC!$B$913)*1000))) -> 0 | W28: =IF(country_selected="Please select",0,V28*VLOOKUP(moist_type, IPCC!$B$99:$C$101, 2, FALSE)*N2O_N_conversion) -> 0 | X28: =($T28*methane+($U28+W28)*Nitrous)/1000 -> 0 | Z28: =IF($E28= "YES", $G40*$T28*methane/1000,0) -> 0 | AA28: =IF($E28= "YES", $H40*$T28*methane/1000,0) -> 0 | AB28: =$G40*$U28*Nitrous/1000 -> 0 | AC28: =$H40*$U28*Nitrous/1000 -> 0 | AD28: =$G40*$W28*Nitrous/1000 -> 0 | AE28: =$H40*$W28*Nitrous/1000 -> 0 | AG28: 0 | AH28: =IF($F28>0, $G40, 0) -> 0 | AI28: =IF($F28>0, $H40, 0) -> 0
A29: Deforestation 7 | B29: ='2.LUC'!$C17 -> Please select | C29: ='2.LUC'!$E17 -> 0 | D29: =IF('2.LUC'!$C17="Please select",0,IF(C29>VLOOKUP($B29,defo!$H$9:$K$16,2,FALSE),VLOOKUP($B29,defo!$H$9:$K$16,2,FALSE),'2.LUC'!$E17))*IF(B29="Mangrove Forest",0.451, 0.47) -> 0 | E29: ='2.LUC'!$G17 -> NO | F29: =IF($B29<> "Please select", IF($E29="YES", VLOOKUP($B29, IPCC!$A$871:$B$906, 2, FALSE),0), 0) -> 0 | G29: ='2.LUC'!$I17 -> Please select | H29: ='2.LUC'!$K17 -> Please select | I29: =IF('2.LUC'!$K17 <> "Please select", '2.LUC'!$K17, IF('2.LUC'!$I17<>"Agroforestry", '2.LUC'!$I17, "Agroforestry - default")) -> Please select | J29: =IF('2.LUC'!$I17 <> "Please select", IF('2.LUC'!BP17=0, INDEX(IPCC!$D$686:$Y$845,MATCH(clim_moist_cont,IPCC!$C$686:$C$845,0),MATCH($I29,IPCC!$D$682:$Y$682,0)), '2.LUC'!BP17), 0) -> 0 | K29: =IF('2.LUC'!$C17<>"Please select",$K15-$D29+$N15,0) -> 0 | L29: =K29*44/12 -> 0 | M29: =IF('2.LUC'!$C17<>"Please select",P15+R15,0) -> 0 | N29: =M29*44/12 -> 0 | O29: =IF($I29<> "Please select", INDEX(IPCC!$B$852:$W$863,MATCH(clim_moist,IPCC!$A$852:$A$863,0),MATCH($I29,IPCC!$B$852:$W$852,0)),0) -> 0 | P29: ='2.LUC'!BV17 -> 0 | Q29: =IF($I29<>"Please select",IF('2.LUC'!BS17=0, $T15*IF(OR(P29=0, P29=""),$O29, P29)-$T15, '2.LUC'!BS17*IF(OR(P29=0, P29=""),$O29, P29)-$T15),0) -> 0 | R29: =Q29*(-44/12)/20 -> 0 | S29: =IF($E29="NO",0,(VLOOKUP($B29,$H$9:$I$16,2,FALSE)-$C29)) -> 0 | T29: =IF($E29="YES", ($S29*VLOOKUP($B29, IPCC!$A$871:$E$906,2, FALSE)*VLOOKUP($B29, IPCC!$A$871:$E$906, 4, FALSE)), 0) -> 0 | U29: =IF($E29="YES", ($S29*VLOOKUP($B29, IPCC!$A$871:$E$906,2, FALSE)*VLOOKUP($B29, IPCC!$A$871:$E$906, 5, FALSE)), 0) -> 0 | V29: =IF($Q29>=0, 0, ((-1)*(($Q29/20*1/IPCC!$B$913)*1000))) -> 0 | W29: =IF(country_selected="Please select",0,V29*VLOOKUP(moist_type, IPCC!$B$99:$C$101, 2, FALSE)*N2O_N_conversion) -> 0 | X29: =($T29*methane+($U29+W29)*Nitrous)/1000 -> 0 | Z29: =IF($E29= "YES", $G41*$T29*methane/1000,0) -> 0 | AA29: =IF($E29= "YES", $H41*$T29*methane/1000,0) -> 0 | AB29: =$G41*$U29*Nitrous/1000 -> 0 | AC29: =$H41*$U29*Nitrous/1000 -> 0 | AD29: =$G41*$W29*Nitrous/1000 -> 0 | AE29: =$H41*$W29*Nitrous/1000 -> 0 | AG29: 0 | AH29: =IF($F29>0, $G41, 0) -> 0 | AI29: =IF($F29>0, $H41, 0) -> 0
A30: Deforestation 8 | B30: ='2.LUC'!$C18 -> Please select | C30: ='2.LUC'!$E18 -> 0 | D30: =IF('2.LUC'!$C18="Please select",0,IF(C30>VLOOKUP($B30,defo!$H$9:$K$16,2,FALSE),VLOOKUP($B30,defo!$H$9:$K$16,2,FALSE),'2.LUC'!$E18))*IF(B30="Mangrove Forest",0.451, 0.47) -> 0 | E30: ='2.LUC'!$G18 -> NO | F30: =IF($B30<> "Please select", IF($E30="YES", VLOOKUP($B30, IPCC!$A$871:$B$906, 2, FALSE),0), 0) -> 0 | G30: ='2.LUC'!$I18 -> Please select | H30: ='2.LUC'!$K18 -> Please select | I30: =IF('2.LUC'!$K18 <> "Please select", '2.LUC'!$K18, IF('2.LUC'!$I18<>"Agroforestry", '2.LUC'!$I18, "Agroforestry - default")) -> Please select | J30: =IF('2.LUC'!$I18 <> "Please select", IF('2.LUC'!BP18=0, INDEX(IPCC!$D$686:$Y$845,MATCH(clim_moist_cont,IPCC!$C$686:$C$845,0),MATCH($I30,IPCC!$D$682:$Y$682,0)), '2.LUC'!BP18), 0) -> 0 | K30: =IF('2.LUC'!$C18<>"Please select",$K16-$D30+$N16,0) -> 0 | L30: =K30*44/12 -> 0 | M30: =IF('2.LUC'!$C18<>"Please select",P16+R16,0) -> 0 | N30: =M30*44/12 -> 0 | O30: =IF($I30<> "Please select", INDEX(IPCC!$B$852:$W$863,MATCH(clim_moist,IPCC!$A$852:$A$863,0),MATCH($I30,IPCC!$B$852:$W$852,0)),0) -> 0 | P30: ='2.LUC'!BV18 -> 0 | Q30: =IF($I30<>"Please select",IF('2.LUC'!BS18=0, $T16*IF(OR(P30=0, P30=""),$O30, P30)-$T16, '2.LUC'!BS18*IF(OR(P30=0, P30=""),$O30, P30)-$T16),0) -> 0 | R30: =Q30*(-44/12)/20 -> 0 | S30: =IF($E30="NO",0,(VLOOKUP($B30,$H$9:$I$16,2,FALSE)-$C30)) -> 0 | T30: =IF($E30="YES", ($S30*VLOOKUP($B30, IPCC!$A$871:$E$906,2, FALSE)*VLOOKUP($B30, IPCC!$A$871:$E$906, 4, FALSE)), 0) -> 0 | U30: =IF($E30="YES", ($S30*VLOOKUP($B30, IPCC!$A$871:$E$906,2, FALSE)*VLOOKUP($B30, IPCC!$A$871:$E$906, 5, FALSE)), 0) -> 0 | V30: =IF($Q30>=0, 0, ((-1)*(($Q30/20*1/IPCC!$B$913)*1000))) -> 0 | W30: =IF(country_selected="Please select",0,V30*VLOOKUP(moist_type, IPCC!$B$99:$C$101, 2, FALSE)*N2O_N_conversion) -> 0 | X30: =($T30*methane+($U30+W30)*Nitrous)/1000 -> 0 | Z30: =IF($E30= "YES", $G42*$T30*methane/1000,0) -> 0 | AA30: =IF($E30= "YES", $H42*$T30*methane/1000,0) -> 0 | AB30: =$G42*$U30*Nitrous/1000 -> 0 | AC30: =$H42*$U30*Nitrous/1000 -> 0 | AD30: =$G42*$W30*Nitrous/1000 -> 0 | AE30: =$H42*$W30*Nitrous/1000 -> 0 | AG30: 0 | AH30: =IF($F30>0, $G42, 0) -> 0 | AI30: =IF($F30>0, $H42, 0) -> 0
AG31: =SUM(AG23:AG30) -> 0 | AH31: =SUM(AH23:AH30) -> 0 | AI31: =SUM(AI23:AI30) -> 0
A32: GHG emissions | B32: Forested Area (ha) | G32: Area deforested (ha) | I32: Biomass loss (AGB + BGB) | K32: Biomass gain (1yr after) | M32: DOM loss (DW + litter) | O32: Soil emissions/removals | Q32: Fire + SOM | S32: Total Balance | U32: Total
A33: Name | B33: Start | C33: Without Project | E33: With Project | G33: Without | H33: With | I33: Without | J33: With | K33: Without | L33: With | M33: Without | N33: With | O33: Without | P33: With | Q33: Without | R33: With | S33: Without | T33: With | U33: Deforestation
B34: t0 | C34: End | D34: Rate | E34: End | F34: Rate | G34: (ha) | H34: (ha) | I34: tCO2 | J34: tCO2 | K34: tCO2 | L34: tCO2 | M34: tCO2 | N34: tCO2 | O34: tCO2-e | P34: tCO2-e | Q34: tCO2-e | R34: tCO2-e | S34: tCO2-e | T34: tCO2-e | U34: tCO2-e | X34: Categories | Y34: Total | Z34: Implementation | AA34: Capitalization
A35: Deforestation 1 | B35: ='2.LUC'!$M11 -> 0 | C35: ='2.LUC'!$N11 -> 0 | D35: =VLOOKUP('2.LUC'!$O11, list!$I$48:$J$50,2,FALSE ) -> Linear | E35: ='2.LUC'!$P11 -> 0 | F35: =VLOOKUP('2.LUC'!$Q11, list!$I$48:$J$50,2,FALSE ) -> Linear | G35: =IF($C35>$B35,0, $B35-$C35) -> 0 | H35: =IF($E35>$B35,0, $B35-$E35) -> 0 | I35: =$L23*($G35) -> 0 | J35: =$H35*($L23) -> 0 | K35: =IF($I35=0,0,IF('2.LUC'!$C11="Please select",0,-($G35*$J23*44/12))) -> 0 | L35: =IF($J35=0,0,IF('2.LUC'!$C11="Please select",0,-($H35*$J23*44/12))) -> 0 | M35: =$N23*($G35) -> 0 | N35: =$N23*$H35 -> 0 | O35: =IF(ABS($R23*(IF($D35="Immediate",IF($G35>0, $G35*MIN(20,time_tot),0), $G35*IF(time_tot>time+20, 20, IF(time_tot<20,(time*VLOOKUP($D35, list!$J$48:$K$50,2,))+(time_tot-time),((MIN(20,time)*VLOOKUP($D35, list!$J$48:$K$50,2,)) + (time_tot-MIN(20,time))-IF($D35="Exponential",time_tot-20+0.217*time*(EXP(4.606*(20-time_tot)/time)-1),((time_tot-20)^2)*(0.5/time))))))))>=ABS(G35*Q23*-44/12), G35*Q23*-44/12, $R23*(IF($D35="Immediate",IF($G35>0, $G35*MIN(20,time_tot),0), $G35*IF(time_tot>time+20, 20, IF(time_tot<20,(time*VLOOKUP($D35, list!$J$48:$K$50,2,))+(time_tot-time),((MIN(20,time)*VLOOKUP($D35, list!$J$48:$K$50,2,)) + (time_tot-MIN(20,time))-IF($D35="Exponential",time_tot-20+0.217*time*(EXP(4.606*(20-time_tot)/time)-1),((time_tot-20)^2)*(0.5/time)))))))) -> 0 | P35: =IF(ABS($R23*(IF($F35="Immediate",IF($H35 > 0, $H35*MIN(20,time_tot),0), $H35*IF(time_tot>time+20,20,IF(time_tot<20,(time*VLOOKUP($F35, list!$J$48:$K$50,2,))+(time_tot-time),((MIN(20,time)*VLOOKUP($F35,list!$J$48:$K$50,2,))+ (time_tot-MIN(20,time))-IF(F35="Exponential",time_tot-20+0.217*time*(EXP(4.606*(20-time_tot)/time)-1),((time_tot-20)^2)*(0.5/time))))))))>=ABS(H35*Q23*-44/12),H35*Q23*-44/12,$R23*(IF($F35="Immediate",IF($H35 > 0, $H35*MIN(20,time_tot),0), $H35*IF(time_tot>time+20,20,IF(time_tot<20,(time*VLOOKUP($F35, list!$J$48:$K$50,2,))+(time_tot-time),((MIN(20,time)*VLOOKUP($F35,list!$J$48:$K$50,2,))+ (time_tot-MIN(20,time))-IF(F35="Exponential",time_tot-20+0.217*time*(EXP(4.606*(20-time_tot)/time)-1),((time_tot-20)^2)*(0.5/time)))))))) -> 0 | Q35: =$G35*$X23 -> 0 | R35: =$H35*$X23 -> 0 | S35: =I35+K35+M35+O35+Q35 -> 0 | T35: =J35+L35+N35+P35+R35 -> 0 | U35: =$T35-$S35 -> 0 | X35: CO2 Biomass | Y35: =SUM(J35:J42)+ SUM(L35:L42)-SUM(I35:I42)-SUM(K35:K42) -> 0 | Z35: =IF(time=0,0,Y35) -> 0 | AA35: =Y35-Z35 -> 0
A36: Deforestation 2 | B36: ='2.LUC'!$M12 -> 0 | C36: ='2.LUC'!$N12 -> 0 | D36: =VLOOKUP('2.LUC'!$O12, list!$I$48:$J$50,2,FALSE ) -> Linear | E36: ='2.LUC'!$P12 -> 0 | F36: =VLOOKUP('2.LUC'!$Q12, list!$I$48:$J$50,2,FALSE ) -> Linear | G36: =IF($C36>$B36,0, $B36-$C36) -> 0 | H36: =IF($E36>$B36,0, $B36-$E36) -> 0 | I36: =$L24*($G36) -> 0 | J36: =$H36*($L24) -> 0 | K36: =IF($I36=0,0,IF('2.LUC'!$C12="Please select",0,-($G36*$J24*44/12))) -> 0 | L36: =IF($J36=0,0,IF('2.LUC'!$C12="Please select",0,-($H36*$J24*44/12))) -> 0 | M36: =$N24*($G36) -> 0 | N36: =$N24*$H36 -> 0 | O36: =IF(ABS($R24*(IF($D36="Immediate",IF($G36>0, $G36*MIN(20,time_tot),0), $G36*IF(time_tot>time+20, 20, IF(time_tot<20,(time*VLOOKUP($D36, list!$J$48:$K$50,2,))+(time_tot-time),((MIN(20,time)*VLOOKUP($D36, list!$J$48:$K$50,2,)) + (time_tot-MIN(20,time))-IF($D36="Exponential",time_tot-20+0.217*time*(EXP(4.606*(20-time_tot)/time)-1),((time_tot-20)^2)*(0.5/time))))))))>=ABS(G36*Q24*-44/12), G36*Q24*-44/12, $R24*(IF($D36="Immediate",IF($G36>0, $G36*MIN(20,time_tot),0), $G36*IF(time_tot>time+20, 20, IF(time_tot<20,(time*VLOOKUP($D36, list!$J$48:$K$50,2,))+(time_tot-time),((MIN(20,time)*VLOOKUP($D36, list!$J$48:$K$50,2,)) + (time_tot-MIN(20,time))-IF($D36="Exponential",time_tot-20+0.217*time*(EXP(4.606*(20-time_tot)/time)-1),((time_tot-20)^2)*(0.5/time)))))))) -> 0 | P36: =IF(ABS($R24*(IF($F36="Immediate",IF($H36 > 0, $H36*MIN(20,time_tot),0), $H36*IF(time_tot>time+20,20,IF(time_tot<20,(time*VLOOKUP($F36, list!$J$48:$K$50,2,))+(time_tot-time),((MIN(20,time)*VLOOKUP($F36,list!$J$48:$K$50,2,))+ (time_tot-MIN(20,time))-IF(F36="Exponential",time_tot-20+0.217*time*(EXP(4.606*(20-time_tot)/time)-1),((time_tot-20)^2)*(0.5/time))))))))>=ABS(H36*Q24*-44/12),H36*Q24*-44/12,$R24*(IF($F36="Immediate",IF($H36 > 0, $H36*MIN(20,time_tot),0), $H36*IF(time_tot>time+20,20,IF(time_tot<20,(time*VLOOKUP($F36, list!$J$48:$K$50,2,))+(time_tot-time),((MIN(20,time)*VLOOKUP($F36,list!$J$48:$K$50,2,))+ (time_tot-MIN(20,time))-IF(F36="Exponential",time_tot-20+0.217*time*(EXP(4.606*(20-time_tot)/time)-1),((time_tot-20)^2)*(0.5/time)))))))) -> 0 | Q36: =$G36*$X24 -> 0 | R36: =$H36*$X24 -> 0 | S36: =I36+K36+M36+O36+Q36 -> 0 | T36: =J36+L36+N36+P36+R36 -> 0 | U36: =$T36-$S36 -> 0 | X36: CO2 DOM | Y36: =SUM(N35:N42)-SUM(M35:M42) -> 0 | Z36: =IF(time=0,0,Y36) -> 0 | AA36: =Y36-Z36 -> 0
A37: Deforestation 3 | B37: ='2.LUC'!$M13 -> 0 | C37: ='2.LUC'!$N13 -> 0 | D37: =VLOOKUP('2.LUC'!$O13, list!$I$48:$J$50,2,FALSE ) -> Linear | E37: ='2.LUC'!$P13 -> 0 | F37: =VLOOKUP('2.LUC'!$Q13, list!$I$48:$J$50,2,FALSE ) -> Linear | G37: =IF($C37>$B37,0, $B37-$C37) -> 0 | H37: =IF($E37>$B37,0, $B37-$E37) -> 0 | I37: =$L25*($G37) -> 0 | J37: =$H37*($L25) -> 0 | K37: =IF($I37=0,0,IF('2.LUC'!$C13="Please select",0,-($G37*$J25*44/12))) -> 0 | L37: =IF($J37=0,0,IF('2.LUC'!$C13="Please select",0,-($H37*$J25*44/12))) -> 0 | M37: =$N25*($G37) -> 0 | N37: =$N25*$H37 -> 0 | O37: =IF(ABS($R25*(IF($D37="Immediate",IF($G37>0, $G37*MIN(20,time_tot),0), $G37*IF(time_tot>time+20, 20, IF(time_tot<20,(time*VLOOKUP($D37, list!$J$48:$K$50,2,))+(time_tot-time),((MIN(20,time)*VLOOKUP($D37, list!$J$48:$K$50,2,)) + (time_tot-MIN(20,time))-IF($D37="Exponential",time_tot-20+0.217*time*(EXP(4.606*(20-time_tot)/time)-1),((time_tot-20)^2)*(0.5/time))))))))>=ABS(G37*Q25*-44/12), G37*Q25*-44/12, $R25*(IF($D37="Immediate",IF($G37>0, $G37*MIN(20,time_tot),0), $G37*IF(time_tot>time+20, 20, IF(time_tot<20,(time*VLOOKUP($D37, list!$J$48:$K$50,2,))+(time_tot-time),((MIN(20,time)*VLOOKUP($D37, list!$J$48:$K$50,2,)) + (time_tot-MIN(20,time))-IF($D37="Exponential",time_tot-20+0.217*time*(EXP(4.606*(20-time_tot)/time)-1),((time_tot-20)^2)*(0.5/time)))))))) -> 0 | P37: =IF(ABS($R25*(IF($F37="Immediate",IF($H37 > 0, $H37*MIN(20,time_tot),0), $H37*IF(time_tot>time+20,20,IF(time_tot<20,(time*VLOOKUP($F37, list!$J$48:$K$50,2,))+(time_tot-time),((MIN(20,time)*VLOOKUP($F37,list!$J$48:$K$50,2,))+ (time_tot-MIN(20,time))-IF(F37="Exponential",time_tot-20+0.217*time*(EXP(4.606*(20-time_tot)/time)-1),((time_tot-20)^2)*(0.5/time))))))))>=ABS(H37*Q25*-44/12),H37*Q25*-44/12,$R25*(IF($F37="Immediate",IF($H37 > 0, $H37*MIN(20,time_tot),0), $H37*IF(time_tot>time+20,20,IF(time_tot<20,(time*VLOOKUP($F37, list!$J$48:$K$50,2,))+(time_tot-time),((MIN(20,time)*VLOOKUP($F37,list!$J$48:$K$50,2,))+ (time_tot-MIN(20,time))-IF(F37="Exponential",time_tot-20+0.217*time*(EXP(4.606*(20-time_tot)/time)-1),((time_tot-20)^2)*(0.5/time)))))))) -> 0 | Q37: =$G37*$X25 -> 0 | R37: =$H37*$X25 -> 0 | S37: =I37+K37+M37+O37+Q37 -> 0 | T37: =J37+L37+N37+P37+R37 -> 0 | U37: =$T37-$S37 -> 0 | X37: CO2 soil | Y37: =SUM(P35:P42)-SUM(O35:O42) -> 0 | Z37: =IF(time=0,0,SUM(P35:P42)-SUM(O35:O42)) -> 0 | AA37: =Y37-Z37 -> 0
A38: Deforestation 4 | B38: ='2.LUC'!$M14 -> 0 | C38: ='2.LUC'!$N14 -> 0 | D38: =VLOOKUP('2.LUC'!$O14, list!$I$48:$J$50,2,FALSE ) -> Linear | E38: ='2.LUC'!$P14 -> 0 | F38: =VLOOKUP('2.LUC'!$Q14, list!$I$48:$J$50,2,FALSE ) -> Linear | G38: =IF($C38>$B38,0, $B38-$C38) -> 0 | H38: =IF($E38>$B38,0, $B38-$E38) -> 0 | I38: =$L26*($G38) -> 0 | J38: =$H38*($L26) -> 0 | K38: =IF($I38=0,0,IF('2.LUC'!$C14="Please select",0,-($G38*$J26*44/12))) -> 0 | L38: =IF($J38=0,0,IF('2.LUC'!$C14="Please select",0,-($H38*$J26*44/12))) -> 0 | M38: =$N26*($G38) -> 0 | N38: =$N26*$H38 -> 0 | O38: =IF(ABS($R26*(IF($D38="Immediate",IF($G38>0, $G38*MIN(20,time_tot),0), $G38*IF(time_tot>time+20, 20, IF(time_tot<20,(time*VLOOKUP($D38, list!$J$48:$K$50,2,))+(time_tot-time),((MIN(20,time)*VLOOKUP($D38, list!$J$48:$K$50,2,)) + (time_tot-MIN(20,time))-IF($D38="Exponential",time_tot-20+0.217*time*(EXP(4.606*(20-time_tot)/time)-1),((time_tot-20)^2)*(0.5/time))))))))>=ABS(G38*Q26*-44/12), G38*Q26*-44/12, $R26*(IF($D38="Immediate",IF($G38>0, $G38*MIN(20,time_tot),0), $G38*IF(time_tot>time+20, 20, IF(time_tot<20,(time*VLOOKUP($D38, list!$J$48:$K$50,2,))+(time_tot-time),((MIN(20,time)*VLOOKUP($D38, list!$J$48:$K$50,2,)) + (time_tot-MIN(20,time))-IF($D38="Exponential",time_tot-20+0.217*time*(EXP(4.606*(20-time_tot)/time)-1),((time_tot-20)^2)*(0.5/time)))))))) -> 0 | P38: =IF(ABS($R26*(IF($F38="Immediate",IF($H38 > 0, $H38*MIN(20,time_tot),0), $H38*IF(time_tot>time+20,20,IF(time_tot<20,(time*VLOOKUP($F38, list!$J$48:$K$50,2,))+(time_tot-time),((MIN(20,time)*VLOOKUP($F38,list!$J$48:$K$50,2,))+ (time_tot-MIN(20,time))-IF(F38="Exponential",time_tot-20+0.217*time*(EXP(4.606*(20-time_tot)/time)-1),((time_tot-20)^2)*(0.5/time))))))))>=ABS(H38*Q26*-44/12),H38*Q26*-44/12,$R26*(IF($F38="Immediate",IF($H38 > 0, $H38*MIN(20,time_tot),0), $H38*IF(time_tot>time+20,20,IF(time_tot<20,(time*VLOOKUP($F38, list!$J$48:$K$50,2,))+(time_tot-time),((MIN(20,time)*VLOOKUP($F38,list!$J$48:$K$50,2,))+ (time_tot-MIN(20,time))-IF(F38="Exponential",time_tot-20+0.217*time*(EXP(4.606*(20-time_tot)/time)-1),((time_tot-20)^2)*(0.5/time)))))))) -> 0 | Q38: =$G38*$X26 -> 0 | R38: =$H38*$X26 -> 0 | S38: =I38+K38+M38+O38+Q38 -> 0 | T38: =J38+L38+N38+P38+R38 -> 0 | U38: =$T38-$S38 -> 0 | X38: CH4 fire | Y38: =SUM(AA23:AA30)-SUM(Z23:Z30) -> 0 | Z38: =IF(time=0, 0, Y38) -> 0 | AA38: =Y38-Z38 -> 0
A39: Deforestation 5 | B39: ='2.LUC'!$M15 -> 0 | C39: ='2.LUC'!$N15 -> 0 | D39: =VLOOKUP('2.LUC'!$O15, list!$I$48:$J$50,2,FALSE ) -> Linear | E39: ='2.LUC'!$P15 -> 0 | F39: =VLOOKUP('2.LUC'!$Q15, list!$I$48:$J$50,2,FALSE ) -> Linear | G39: =IF($C39>$B39,0, $B39-$C39) -> 0 | H39: =IF($E39>$B39,0, $B39-$E39) -> 0 | I39: =$L27*($G39) -> 0 | J39: =$H39*($L27) -> 0 | K39: =IF($I39=0,0,IF('2.LUC'!$C15="Please select",0,-($G39*$J27*44/12))) -> 0 | L39: =IF($J39=0,0,IF('2.LUC'!$C15="Please select",0,-($H39*$J27*44/12))) -> 0 | M39: =$N27*($G39) -> 0 | N39: =$N27*$H39 -> 0 | O39: =IF(ABS($R27*(IF($D39="Immediate",IF($G39>0, $G39*MIN(20,time_tot),0), $G39*IF(time_tot>time+20, 20, IF(time_tot<20,(time*VLOOKUP($D39, list!$J$48:$K$50,2,))+(time_tot-time),((MIN(20,time)*VLOOKUP($D39, list!$J$48:$K$50,2,)) + (time_tot-MIN(20,time))-IF($D39="Exponential",time_tot-20+0.217*time*(EXP(4.606*(20-time_tot)/time)-1),((time_tot-20)^2)*(0.5/time))))))))>=ABS(G39*Q27*-44/12), G39*Q27*-44/12, $R27*(IF($D39="Immediate",IF($G39>0, $G39*MIN(20,time_tot),0), $G39*IF(time_tot>time+20, 20, IF(time_tot<20,(time*VLOOKUP($D39, list!$J$48:$K$50,2,))+(time_tot-time),((MIN(20,time)*VLOOKUP($D39, list!$J$48:$K$50,2,)) + (time_tot-MIN(20,time))-IF($D39="Exponential",time_tot-20+0.217*time*(EXP(4.606*(20-time_tot)/time)-1),((time_tot-20)^2)*(0.5/time)))))))) -> 0 | P39: =IF(ABS($R27*(IF($F39="Immediate",IF($H39 > 0, $H39*MIN(20,time_tot),0), $H39*IF(time_tot>time+20,20,IF(time_tot<20,(time*VLOOKUP($F39, list!$J$48:$K$50,2,))+(time_tot-time),((MIN(20,time)*VLOOKUP($F39,list!$J$48:$K$50,2,))+ (time_tot-MIN(20,time))-IF(F39="Exponential",time_tot-20+0.217*time*(EXP(4.606*(20-time_tot)/time)-1),((time_tot-20)^2)*(0.5/time))))))))>=ABS(H39*Q27*-44/12),H39*Q27*-44/12,$R27*(IF($F39="Immediate",IF($H39 > 0, $H39*MIN(20,time_tot),0), $H39*IF(time_tot>time+20,20,IF(time_tot<20,(time*VLOOKUP($F39, list!$J$48:$K$50,2,))+(time_tot-time),((MIN(20,time)*VLOOKUP($F39,list!$J$48:$K$50,2,))+ (time_tot-MIN(20,time))-IF(F39="Exponential",time_tot-20+0.217*time*(EXP(4.606*(20-time_tot)/time)-1),((time_tot-20)^2)*(0.5/time)))))))) -> 0 | Q39: =$G39*$X27 -> 0 | R39: =$H39*$X27 -> 0 | S39: =I39+K39+M39+O39+Q39 -> 0 | T39: =J39+L39+N39+P39+R39 -> 0 | U39: =$T39-$S39 -> 0 | X39: N2O fire | Y39: =SUM(AC23:AC30)-SUM(AB23:AB30) -> 0 | Z39: =IF(time=0, 0, Y39) -> 0 | AA39: =Y39-Z39 -> 0
